Workbook
Name _b2: #REF!
Name _b2: #REF!
Name a: #REF!
Name a: #REF!
Name AccountList2007: #REF!
Name AccountList2007: #REF!
Name AccountList2008: #REF!
Name AccountList2008: #REF!
Name Agg_Marman_Claims: #REF!
Name Agg_Marman_Claims: #REF!
Name Agg_Marman_Summary: #REF!
Name Agg_Marman_Summary: #REF!
Name Aggregate_Summary: #REF!
Name Aggregate_Summary: #REF!
Name Avg_Delay: '[1]Frequency analysis'!$X$14
Name Binder_Table: [2]Console!$B$156:$C$172
Name binder_table_mid: [2]Console!$B$156:$G$172
Name biz_type_table: [2]Console!$B$70:$C$71
Name biz_type_table_mid: [2]Console!$B$70:$G$71
Name Claims_Inflation: '2. Claims data'!$D$6
Name cli_output2: #REF!
Name cli_output2: #REF!
Name COB_BT_Combo_Table: [2]Console!$B$176:$C$194
Name COB_BT_Combo_Table_mid: [2]Console!$B$176:$G$194
Name COB_table: [2]Console!$B$75:$C$86
Name COB_table_mid: [2]Console!$B$75:$G$86
Name Company: #REF!
Name Company: #REF!
Name Contract_Basis: [3]Assumptions!$L$7
Name Contract_length_table: [2]Console!$B$90:$C$93
Name Contract_length_table_mid: [2]Console!$B$90:$G$93
Name Corr_Factor: [3]Assumptions!$L$13
Name country_table: [2]Console!$K$74:$L$182
Name country_table_mid: [2]Console!$K$74:$P$182
Name csi: [4]Assumptions!$C$28
Name csi_client: #REF!
Name csi_client: #REF!
Name csi_market: #REF!
Name csi_market: #REF!
Name csi_mkt: [4]Aggregation!#REF!
Name csi_mkt: [4]Aggregation!#REF!
Name csi_old: #REF!
Name csi_old: #REF!
Name csi_orig: [4]Aggregation!$D$35
Name csi_std_client: #REF!
Name csi_std_client: #REF!
Name CurrentYear: #REF!
Name CurrentYear: #REF!
Name Data_as_at_date: '2. Claims data'!$D$3
Name Data_Set: '[5]1. IBNR Calculations'!$W$7
Name database1: '[6]2007 vs 2008 (2)'!$A$8:$T$130
Name Database2: '[6]2007 vs 2008'!$A$8:$T$130
Name Dcsi_mkt: [4]Aggregation!#REF!
Name Dcsi_mkt: [4]Aggregation!#REF!
Name Default_Inflation: [3]Assumptions!$L$9
Name disct_rate_cli: #REF!
Name disct_rate_cli: #REF!
Name disct_rate_mkt: #REF!
Name disct_rate_mkt: #REF!
Name dlambda_client: #REF!

Sheet 00. DISCLAIMER
B4: This software is intended for purely educational purposes and as supporting material for the textbook "Pricing in General Insurance" by Pietro Parodi and comes with no guarantee. It should not be relied upon for use in a professional context. If you find errors in the code, you are welcome to notify them (pietro_parodi@yahoo.com) and they will be corrected in a successive version of the software.

Sheet 0. Disclaimer
B2: 这个excel文件将展示如何预测最终索赔次数

Sheet 1. Exposure data
A1: Historic exposure data | E1: Exposure inflation | F1: 0.04
A3: Fiscal year | B3: Turnover (x 1€m) | D3: Policy year | E3: Turnover (x 1€m) - aligned to policy year | F3: Turnover (x 1€m) - revalued @ 4% p.a. | H3: Employee Numbers
A4: 2005 | B4: 311.19 | D4: 2005 | E4: =B4 -> 311.19 | F4: =E4*(1+$F$1)^(2012-D4) -> 409.50481 | H4: 12696
A5: 2006 | B5: 381.975 | D5: 2006 | E5: =B5 -> 381.975 | F5: =E5*(1+$F$1)^(2012-D5) -> 483.32023 | H5: 15964
A6: 2007 | B6: 450.23 | D6: 2007 | E6: =B6 -> 450.23 | F6: =E6*(1+$F$1)^(2012-D6) -> 547.77364 | H6: 16706
A7: 2008 | B7: 514.58 | D7: 2008 | E7: =B7 -> 514.58 | F7: =E7*(1+$F$1)^(2012-D7) -> 601.98582 | H7: 17831
A8: 2009 | B8: 675.84 | D8: 2009 | E8: =B8 -> 675.84 | F8: =E8*(1+$F$1)^(2012-D8) -> 760.22809 | H8: 23301
A9: 2010 | B9: 773.96 | D9: 2010 | E9: =B9 -> 773.96 | F9: =E9*(1+$F$1)^(2012-D9) -> 837.11514 | H9: 26377
A10: 2011 | B10: 837.045 | D10: 2011 | E10: =B10 -> 837.045 | F10: =E10*(1+$F$1)^(2012-D10) -> 870.5268 | H10: 27529
A11: 2012 | B11: 1057.54 | D11: 2012 | E11: =B11 -> 1057.54 | F11: =E11*(1+$F$1)^(2012-D11) -> 1057.54 | H11: 29497
A12: 2013 | B12: 1134.21 | D12: 2013 | E12: =B12 -> 1134.21 | F12: =E12*(1+$F$1)^(2012-D12) -> 1090.5865 | H12: 32373
A13: 2014 | B13: 1164.35 | D13: 2014 | E13: =B13 -> 1164.35 | F13: =E13*(1+$F$1)^(2012-D13) -> 1076.507 | H13: 34375
A14: 2015 | B14: 1265 | D14: 2015 | E14: =B14 -> 1265 | F14: =E14*(1+$F$1)^(2012-D14) -> 1124.5804 | H14: 37290

Sheet 2. Claims data
U1: 案例研究中的样本的延迟信息(以年为单位)具有下面两个特点：(a)同一案件的延迟信息(以天为单位)相同(b)。请注意，我们案例研究中的保单在4月1日生效，因此，损失之间存在明显的保单年度不匹配。 由于没有关于案件赔款量化日期和以前的非零赔案何时被调回零的信息。因此对于这个特定的数据集，我们将假设量化日期与报告日期相同，可以忽略索赔准备金为零的案件。
D2: ASSUMPTIONS
C3: Data as-at date | D3: 41973 | F3: Earliest year | G3: =MIN(Table1[Policy Year]) -> 2005
C4: Policy inception month | D4: 4 | F4: Latest year | G4: =MAX(Table1[Policy Year]) -> 2014
C5: Revalue at | D5: 42278 | F5: Earliest year (shifted) | G5: =MIN(Table1[Policy Year (shifted)]) -> 2004
C6: Claims inflation | D6: 0.05 | F6: Latest year (shifted) | G6: =MAX(Table1[Policy Year (shifted)]) -> 2013
C7: Destination currency | D7: GBP | F7: Earliest month | G7: =Earliest_Year*12+Policy_Inception_Month -> 24064
C8: Exchange rate | D8: 1 | F8: Latest third | G8: =MAX(Table1[Reporting third]) -> 28
C9: Policy inception month (shifted) | D9: 12
AB10: 变换后的保单年 | AC10: 变换后的保单年 | AD10: 变换后的延迟日期
F11: 根据新保单生效月调整保单年 | I11: 已付 | J11: 未付 | K11: 已发生 | L11: 费用 | M11: 追偿 | O11: 非零 | P11: 已发生损失 | Q11: 重估值的已发生损失 | R11: 报告延迟 | T11: 风险暴露
A12: Claim ID | B12: Claimant Name | C12: Class of Business | D12: Loss date | E12: Reporting date | F12: Policy Year | G12: Claim description | H12: Original currency | I12: Paid | J12: Outstanding | K12: Total incurred | L12: Fees | M12: Recoveries | N12: Overall amount | O12: Non-zero? (1=Yes) | P12: Overall (destination currency) | Q12: Overall amount (revalued) | R12: Delay (days) | S12: Claim Status | T12: Exposure | U12: Reporting year | V12: Delay (years) | W12: Delay (days)2 | X12: Policy third | Y12: Reporting third | Z12: Delay (thirds) | AA12: % O/S | AB12: Policy Year (shifted) | AC12: Reporting year (shifted) | AD12: Delay (shifted)
A13: Claim_1 | B13: Name_1 | C13: Public Liability Bodily Injury | D13: 40195 | E13: 40561 | F13: =IF(MONTH(Table1[[#This Row],[Loss date]])<Policy_Inception_Month,YEAR(Table1[[#This Row],[Loss date]])-1,YEAR(Table1[[#This Row],[Loss date]])) -> 2009 | G13: Contact With | H13: GBP | I13: 17056.23 | J13: 0 | K13: 17056.23 | L13: 0 | M13: 0 | N13: 17056.23 | O13: =IF(Table1[[#This Row],[Overall amount]]=0,0,1) -> 1 | P13: =Table1[[#This Row],[Overall amount]]*Exchange_Rate -> 17056.23 | Q13: =Table1[[#This Row],[Overall (destination currency)]]*(1+Claims_Inflation)^((Revalue_at_date-Table1[[#This Row],[Loss date]])/365.25) -> 22528.092 | R13: =INT(Table1[[#This Row],[Reporting date]])-INT(Table1[[#This Row],[Loss date]]) -> 366 | S13: Closed | T13: =VLOOKUP(Table1[[#This Row],[Policy Year]],exposure_table,3,FALSE) -> 760.22809 | U13: =IF(MONTH(Table1[[#This Row],[Reporting date]])<Policy_Inception_Month,YEAR(Table1[[#This Row],[Reporting date]])-1,YEAR(Table1[[#This Row],[Reporting date]])) -> 2010 | V13: =Table1[[#This Row],[Reporting year]]-Table1[[#This Row],[Policy Year]] -> 1 | W13: =INT(Table1[[#This Row],[Reporting date]])-INT(Table1[[#This Row],[Loss date]]) -> 366 | X13: =INT((YEAR(Table1[[#This Row],[Loss date]])*12+MONTH(Table1[[#This Row],[Loss date]])-Earliest_Month)/4) -> 14 | Y13: =INT((YEAR(Table1[[#This Row],[Reporting date]])*12+MONTH(Table1[[#This Row],[Reporting date]])-Earliest_Month)/4) -> 17 | Z13: =Table1[[#This Row],[Reporting third]]-Table1[[#This Row],[Policy third]] -> 3 | AA13: =IF(Table1[[#This Row],[Overall amount]]=0,"N/A",Table1[[#This Row],[Outstanding]]/Table1[[#This Row],[Overall amount]]) -> 0 | AB13: =IF(MONTH(Table1[[#This Row],[Loss date]])<Pol_Inc_Month_Shifted,YEAR(Table1[[#This Row],[Loss date]])-1,YEAR(Table1[[#This Row],[Loss date]])) -> 2009 | AC13: =IF(MONTH(Table1[[#This Row],[Reporting date]])<Pol_Inc_Month_Shifted,YEAR(Table1[[#This Row],[Reporting date]])-1,YEAR(Table1[[#This Row],[Reporting date]])) -> 2010 | AD13: =Table1[[#This Row],[Reporting year (shifted)]]-Table1[[#This Row],[Policy Year (shifted)]] -> 1 | AF13: =COUNTIFS(Table1[Policy Year (shifted)],2010, Table1[Non-zero? (1=Yes)],1) -> 268
A14: Claim_2 | B14: Name_2 | C14: Public Liability Bodily Injury | D14: 39144 | E14: 39195 | F14: =IF(MONTH(Table1[[#This Row],[Loss date]])<Policy_Inception_Month,YEAR(Table1[[#This Row],[Loss date]])-1,YEAR(Table1[[#This Row],[Loss date]])) -> 2006 | G14: Slip,Trip Or Fall-Same Level | H14: GBP | I14: 27297.096 | J14: 0 | K14: 27297.096 | L14: 0 | M14: 0 | N14: 27297.096 | O14: =IF(Table1[[#This Row],[Overall amount]]=0,0,1) -> 1 | P14: =Table1[[#This Row],[Overall amount]]*Exchange_Rate -> 27297.096 | Q14: =Table1[[#This Row],[Overall (destination currency)]]*(1+Claims_Inflation)^((Revalue_at_date-Table1[[#This Row],[Loss date]])/365.25) -> 41488.68 | R14: =INT(Table1[[#This Row],[Reporting date]])-INT(Table1[[#This Row],[Loss date]]) -> 51 | S14: Closed | T14: =VLOOKUP(Table1[[#This Row],[Policy Year]],exposure_table,3,FALSE) -> 483.32023 | U14: =IF(MONTH(Table1[[#This Row],[Reporting date]])<Policy_Inception_Month,YEAR(Table1[[#This Row],[Reporting date]])-1,YEAR(Table1[[#This Row],[Reporting date]])) -> 2007 | V14: =Table1[[#This Row],[Reporting year]]-Table1[[#This Row],[Policy Year]] -> 1 | W14: =INT(Table1[[#This Row],[Reporting date]])-INT(Table1[[#This Row],[Loss date]]) -> 51 | X14: =INT((YEAR(Table1[[#This Row],[Loss date]])*12+MONTH(Table1[[#This Row],[Loss date]])-Earliest_Month)/4) -> 5 | Y14: =INT((YEAR(Table1[[#This Row],[Reporting date]])*12+MONTH(Table1[[#This Row],[Reporting date]])-Earliest_Month)/4) -> 6 | Z14: =Table1[[#This Row],[Reporting third]]-Table1[[#This Row],[Policy third]] -> 1 | AA14: =IF(Table1[[#This Row],[Overall amount]]=0,"N/A",Table1[[#This Row],[Outstanding]]/Table1[[#This Row],[Overall amount]]) -> 0 | AB14: =IF(MONTH(Table1[[#This Row],[Loss date]])<Pol_Inc_Month_Shifted,YEAR(Table1[[#This Row],[Loss date]])-1,YEAR(Table1[[#This Row],[Loss date]])) -> 2006 | AC14: =IF(MONTH(Table1[[#This Row],[Reporting date]])<Pol_Inc_Month_Shifted,YEAR(Table1[[#This Row],[Reporting date]])-1,YEAR(Table1[[#This Row],[Reporting date]])) -> 2006 | AD14: =Table1[[#This Row],[Reporting year (shifted)]]-Table1[[#This Row],[Policy Year (shifted)]] -> 0
A15: Claim_3 | B15: Name_3 | C15: Public Liability Bodily Injury | D15: 39268 | E15: 39622 | F15: =IF(MONTH(Table1[[#This Row],[Loss date]])<Policy_Inception_Month,YEAR(Table1[[#This Row],[Loss date]])-1,YEAR(Table1[[#This Row],[Loss date]])) -> 2007 | G15: Slip,Trip Or Fall-Elevated Surfaces | H15: GBP | I15: 2230.5459 | J15: 0 | K15: 2230.5459 | L15: 0 | M15: 0 | N15: 2230.5459 | O15: =IF(Table1[[#This Row],[Overall amount]]=0,0,1) -> 1 | P15: =Table1[[#This Row],[Overall amount]]*Exchange_Rate -> 2230.5459 | Q15: =Table1[[#This Row],[Overall (destination currency)]]*(1+Claims_Inflation)^((Revalue_at_date-Table1[[#This Row],[Loss date]])/365.25) -> 3334.5 | R15: =INT(Table1[[#This Row],[Reporting date]])-INT(Table1[[#This Row],[Loss date]]) -> 354 | S15: Closed | T15: =VLOOKUP(Table1[[#This Row],[Policy Year]],exposure_table,3,FALSE) -> 547.77364 | U15: =IF(MONTH(Table1[[#This Row],[Reporting date]])<Policy_Inception_Month,YEAR(Table1[[#This Row],[Reporting date]])-1,YEAR(Table1[[#This Row],[Reporting date]])) -> 2008 | V15: =Table1[[#This Row],[Reporting year]]-Table1[[#This Row],[Policy Year]] -> 1 | W15: =INT(Table1[[#This Row],[Reporting date]])-INT(Table1[[#This Row],[Loss date]]) -> 354 | X15: =INT((YEAR(Table1[[#This Row],[Loss date]])*12+MONTH(Table1[[#This Row],[Loss date]])-Earliest_Month)/4) -> 6 | Y15: =INT((YEAR(Table1[[#This Row],[Reporting date]])*12+MONTH(Table1[[#This Row],[Reporting date]])-Earliest_Month)/4) -> 9 | Z15: =Table1[[#This Row],[Reporting third]]-Table1[[#This Row],[Policy third]] -> 3 | AA15: =IF(Table1[[#This Row],[Overall amount]]=0,"N/A",Table1[[#This Row],[Outstanding]]/Table1[[#This Row],[Overall amount]]) -> 0 | AB15: =IF(MONTH(Table1[[#This Row],[Loss date]])<Pol_Inc_Month_Shifted,YEAR(Table1[[#This Row],[Loss date]])-1,YEAR(Table1[[#This Row],[Loss date]])) -> 2006 | AC15: =IF(MONTH(Table1[[#This Row],[Reporting date]])<Pol_Inc_Month_Shifted,YEAR(Table1[[#This Row],[Reporting date]])-1,YEAR(Table1[[#This Row],[Reporting date]])) -> 2007 | AD15: =Table1[[#This Row],[Reporting year (shifted)]]-Table1[[#This Row],[Policy Year (shifted)]] -> 1
A16: Claim_4 | B16: Name_4 | C16: Public Liability Bodily Injury | D16: 39605 | E16: 40201 | F16: =IF(MONTH(Table1[[#This Row],[Loss date]])<Policy_Inception_Month,YEAR(Table1[[#This Row],[Loss date]])-1,YEAR(Table1[[#This Row],[Loss date]])) -> 2008 | G16: Slip,Trip Or Fall-Same Level | H16: GBP | I16: 13516.419 | J16: 0 | K16: 13516.419 | L16: 0 | M16: 1189.4449 | N16: 12326.974 | O16: =IF(Table1[[#This Row],[Overall amount]]=0,0,1) -> 1 | P16: =Table1[[#This Row],[Overall amount]]*Exchange_Rate -> 12326.974 | Q16: =Table1[[#This Row],[Overall (destination currency)]]*(1+Claims_Inflation)^((Revalue_at_date-Table1[[#This Row],[Loss date]])/365.25) -> 17616.743 | R16: =INT(Table1[[#This Row],[Reporting date]])-INT(Table1[[#This Row],[Loss date]]) -> 596 | S16: Closed | T16: =VLOOKUP(Table1[[#This Row],[Policy Year]],exposure_table,3,FALSE) -> 601.98582 | U16: =IF(MONTH(Table1[[#This Row],[Reporting date]])<Policy_Inception_Month,YEAR(Table1[[#This Row],[Reporting date]])-1,YEAR(Table1[[#This Row],[Reporting date]])) -> 2009 | V16: =Table1[[#This Row],[Reporting year]]-Table1[[#This Row],[Policy Year]] -> 1 | W16: =INT(Table1[[#This Row],[Reporting date]])-INT(Table1[[#This Row],[Loss date]]) -> 596 | X16: =INT((YEAR(Table1[[#This Row],[Loss date]])*12+MONTH(Table1[[#This Row],[Loss date]])-Earliest_Month)/4) -> 9 | Y16: =INT((YEAR(Table1[[#This Row],[Reporting date]])*12+MONTH(Table1[[#This Row],[Reporting date]])-Earliest_Month)/4) -> 14 | Z16: =Table1[[#This Row],[Reporting third]]-Table1[[#This Row],[Policy third]] -> 5 | AA16: =IF(Table1[[#This Row],[Overall amount]]=0,"N/A",Table1[[#This Row],[Outstanding]]/Table1[[#This Row],[Overall amount]]) -> 0 | AB16: =IF(MONTH(Table1[[#This Row],[Loss date]])<Pol_Inc_Month_Shifted,YEAR(Table1[[#This Row],[Loss date]])-1,YEAR(Table1[[#This Row],[Loss date]])) -> 2007 | AC16: =IF(MONTH(Table1[[#This Row],[Reporting date]])<Pol_Inc_Month_Shifted,YEAR(Table1[[#This Row],[Reporting date]])-1,YEAR(Table1[[#This Row],[Reporting date]])) -> 2009 | AD16: =Table1[[#This Row],[Reporting year (shifted)]]-Table1[[#This Row],[Policy Year (shifted)]] -> 2
A17: Claim_5 | B17: Name_5 | C17: Public Liability Bodily Injury | D17: 40344 | E17: 40348 | F17: =IF(MONTH(Table1[[#This Row],[Loss date]])<Policy_Inception_Month,YEAR(Table1[[#This Row],[Loss date]])-1,YEAR(Table1[[#This Row],[Loss date]])) -> 2010 | G17: Caught Between Moving Objects | H17: GBP | I17: 873.50459 | J17: 0 | K17: 873.50459 | L17: 0 | M17: 0 | N17: 873.50459 | O17: =IF(Table1[[#This Row],[Overall amount]]=0,0,1) -> 1 | P17: =Table1[[#This Row],[Overall amount]]*Exchange_Rate -> 873.50459 | Q17: =Table1[[#This Row],[Overall (destination currency)]]*(1+Claims_Inflation)^((Revalue_at_date-Table1[[#This Row],[Loss date]])/365.25) -> 1131 | R17: =INT(Table1[[#This Row],[Reporting date]])-INT(Table1[[#This Row],[Loss date]]) -> 4 | S17: Closed | T17: =VLOOKUP(Table1[[#This Row],[Policy Year]],exposure_table,3,FALSE) -> 837.11514 | U17: =IF(MONTH(Table1[[#This Row],[Reporting date]])<Policy_Inception_Month,YEAR(Table1[[#This Row],[Reporting date]])-1,YEAR(Table1[[#This Row],[Reporting date]])) -> 2010 | V17: =Table1[[#This Row],[Reporting year]]-Table1[[#This Row],[Policy Year]] -> 0 | W17: =INT(Table1[[#This Row],[Reporting date]])-INT(Table1[[#This Row],[Loss date]]) -> 4 | X17: =INT((YEAR(Table1[[#This Row],[Loss date]])*12+MONTH(Table1[[#This Row],[Loss date]])-Earliest_Month)/4) -> 15 | Y17: =INT((YEAR(Table1[[#This Row],[Reporting date]])*12+MONTH(Table1[[#This Row],[Reporting date]])-Earliest_Month)/4) -> 15 | Z17: =Table1[[#This Row],[Reporting third]]-Table1[[#This Row],[Policy third]] -> 0 | AA17: =IF(Table1[[#This Row],[Overall amount]]=0,"N/A",Table1[[#This Row],[Outstanding]]/Table1[[#This Row],[Overall amount]]) -> 0 | AB17: =IF(MONTH(Table1[[#This Row],[Loss date]])<Pol_Inc_Month_Shifted,YEAR(Table1[[#This Row],[Loss date]])-1,YEAR(Table1[[#This Row],[Loss date]])) -> 2009 | AC17: =IF(MONTH(Table1[[#This Row],[Reporting date]])<Pol_Inc_Month_Shifted,YEAR(Table1[[#This Row],[Reporting date]])-1,YEAR(Table1[[#This Row],[Reporting date]])) -> 2009 | AD17: =Table1[[#This Row],[Reporting year (shifted)]]-Table1[[#This Row],[Policy Year (shifted)]] -> 0
A18: Claim_6 | B18: Name_6 | C18: Public Liability Bodily Injury | D18: 39284 | E18: 39691 | F18: =IF(MONTH(Table1[[#This Row],[Loss date]])<Policy_Inception_Month,YEAR(Table1[[#This Row],[Loss date]])-1,YEAR(Table1[[#This Row],[Loss date]])) -> 2007 | G18: Slip,Trip Or Fall-Same Level | H18: GBP | I18: 866.10894 | J18: 0 | K18: 866.10894 | L18: 0 | M18: 0 | N18: 866.10894 | O18: =IF(Table1[[#This Row],[Overall amount]]=0,0,1) -> 1 | P18: =Table1[[#This Row],[Overall amount]]*Exchange_Rate -> 866.10894 | Q18: =Table1[[#This Row],[Overall (destination currency)]]*(1+Claims_Inflation)^((Revalue_at_date-Table1[[#This Row],[Loss date]])/365.25) -> 1292.004 | R18: =INT(Table1[[#This Row],[Reporting date]])-INT(Table1[[#This Row],[Loss date]]) -> 407 | S18: Closed | T18: =VLOOKUP(Table1[[#This Row],[Policy Year]],exposure_table,3,FALSE) -> 547.77364 | U18: =IF(MONTH(Table1[[#This Row],[Reporting date]])<Policy_Inception_Month,YEAR(Table1[[#This Row],[Reporting date]])-1,YEAR(Table1[[#This Row],[Reporting date]])) -> 2008 | V18: =Table1[[#This Row],[Reporting year]]-Table1[[#This Row],[Policy Year]] -> 1 | W18: =INT(Table1[[#This Row],[Reporting date]])-INT(Table1[[#This Row],[Loss date]]) -> 407 | X18: =INT((YEAR(Table1[[#This Row],[Loss date]])*12+MONTH(Table1[[#This Row],[Loss date]])-Earliest_Month)/4) -> 6 | Y18: =INT((YEAR(Table1[[#This Row],[Reporting date]])*12+MONTH(Table1[[#This Row],[Reporting date]])-Earliest_Month)/4) -> 10 | Z18: =Table1[[#This Row],[Reporting third]]-Table1[[#This Row],[Policy third]] -> 4 | AA18: =IF(Table1[[#This Row],[Overall amount]]=0,"N/A",Table1[[#This Row],[Outstanding]]/Table1[[#This Row],[Overall amount]]) -> 0 | AB18: =IF(MONTH(Table1[[#This Row],[Loss date]])<Pol_Inc_Month_Shifted,YEAR(Table1[[#This Row],[Loss date]])-1,YEAR(Table1[[#This Row],[Loss date]])) -> 2006 | AC18: =IF(MONTH(Table1[[#This Row],[Reporting date]])<Pol_Inc_Month_Shifted,YEAR(Table1[[#This Row],[Reporting date]])-1,YEAR(Table1[[#This Row],[Reporting date]])) -> 2007 | AD18: =Table1[[#This Row],[Reporting year (shifted)]]-Table1[[#This Row],[Policy Year (shifted)]] -> 1
A19: Claim_7 | B19: Name_7 | C19: Public Liability Bodily Injury | D19: 40055 | E19: 40111 | F19: =IF(MONTH(Table1[[#This Row],[Loss date]])<Policy_Inception_Month,YEAR(Table1[[#This Row],[Loss date]])-1,YEAR(Table1[[#This Row],[Loss date]])) -> 2009 | G19: Slip,Trip Or Fall-Same Level | H19: GBP | I19: 413.74811 | J19: 0 | K19: 413.74811 | L19: 0 | M19: 0 | N19: 413.74811 | O19: =IF(Table1[[#This Row],[Overall amount]]=0,0,1) -> 1 | P19: =Table1[[#This Row],[Overall amount]]*Exchange_Rate -> 413.74811 | Q19: =Table1[[#This Row],[Overall (destination currency)]]*(1+Claims_Inflation)^((Revalue_at_date-Table1[[#This Row],[Loss date]])/365.25) -> 556.8 | R19: =INT(Table1[[#This Row],[Reporting date]])-INT(Table1[[#This Row],[Loss date]]) -> 56 | S19: Closed | T19: =VLOOKUP(Table1[[#This Row],[Policy Year]],exposure_table,3,FALSE) -> 760.22809 | U19: =IF(MONTH(Table1[[#This Row],[Reporting date]])<Policy_Inception_Month,YEAR(Table1[[#This Row],[Reporting date]])-1,YEAR(Table1[[#This Row],[Reporting date]])) -> 2009 | V19: =Table1[[#This Row],[Reporting year]]-Table1[[#This Row],[Policy Year]] -> 0 | W19: =INT(Table1[[#This Row],[Reporting date]])-INT(Table1[[#This Row],[Loss date]]) -> 56 | X19: =INT((YEAR(Table1[[#This Row],[Loss date]])*12+MONTH(Table1[[#This Row],[Loss date]])-Earliest_Month)/4) -> 13 | Y19: =INT((YEAR(Table1[[#This Row],[Reporting date]])*12+MONTH(Table1[[#This Row],[Reporting date]])-Earliest_Month)/4) -> 13 | Z19: =Table1[[#This Row],[Reporting third]]-Table1[[#This Row],[Policy third]] -> 0 | AA19: =IF(Table1[[#This Row],[Overall amount]]=0,"N/A",Table1[[#This Row],[Outstanding]]/Table1[[#This Row],[Overall amount]]) -> 0 | AB19: =IF(MONTH(Table1[[#This Row],[Loss date]])<Pol_Inc_Month_Shifted,YEAR(Table1[[#This Row],[Loss date]])-1,YEAR(Table1[[#This Row],[Loss date]])) -> 2008 | AC19: =IF(MONTH(Table1[[#This Row],[Reporting date]])<Pol_Inc_Month_Shifted,YEAR(Table1[[#This Row],[Reporting date]])-1,YEAR(Table1[[#This Row],[Reporting date]])) -> 2008 | AD19: =Table1[[#This Row],[Reporting year (shifted)]]-Table1[[#This Row],[Policy Year (shifted)]] -> 0
A20: Claim_8 | B20: Name_8 | C20: Public Liability Bodily Injury | D20: 39298 | E20: 39487 | F20: =IF(MONTH(Table1[[#This Row],[Loss date]])<Policy_Inception_Month,YEAR(Table1[[#This Row],[Loss date]])-1,YEAR(Table1[[#This Row],[Loss date]])) -> 2007 | G20: Caught Between Moving Objects | H20: GBP | I20: 38016.942 | J20: 0 | K20: 38016.942 | L20: 0 | M20: 0 | N20: 38016.942 | O20: =IF(Table1[[#This Row],[Overall amount]]=0,0,1) -> 1 | P20: =Table1[[#This Row],[Overall amount]]*Exchange_Rate -> 38016.942 | Q20: =Table1[[#This Row],[Overall (destination currency)]]*(1+Claims_Inflation)^((Revalue_at_date-Table1[[#This Row],[Loss date]])/365.25) -> 56605.2 | R20: =INT(Table1[[#This Row],[Reporting date]])-INT(Table1[[#This Row],[Loss date]]) -> 189 | S20: Closed | T20: =VLOOKUP(Table1[[#This Row],[Policy Year]],exposure_table,3,FALSE) -> 547.77364 | U20: =IF(MONTH(Table1[[#This Row],[Reporting date]])<Policy_Inception_Month,YEAR(Table1[[#This Row],[Reporting date]])-1,YEAR(Table1[[#This Row],[Reporting date]])) -> 2007 | V20: =Table1[[#This Row],[Reporting year]]-Table1[[#This Row],[Policy Year]] -> 0 | W20: =INT(Table1[[#This Row],[Reporting date]])-INT(Table1[[#This Row],[Loss date]]) -> 189 | X20: =INT((YEAR(Table1[[#This Row],[Loss date]])*12+MONTH(Table1[[#This Row],[Loss date]])-Earliest_Month)/4) -> 7 | Y20: =INT((YEAR(Table1[[#This Row],[Reporting date]])*12+MONTH(Table1[[#This Row],[Reporting date]])-Earliest_Month)/4) -> 8 | Z20: =Table1[[#This Row],[Reporting third]]-Table1[[#This Row],[Policy third]] -> 1 | AA20: =IF(Table1[[#This Row],[Overall amount]]=0,"N/A",Table1[[#This Row],[Outstanding]]/Table1[[#This Row],[Overall amount]]) -> 0 | AB20: =IF(MONTH(Table1[[#This Row],[Loss date]])<Pol_Inc_Month_Shifted,YEAR(Table1[[#This Row],[Loss date]])-1,YEAR(Table1[[#This Row],[Loss date]])) -> 2006 | AC20: =IF(MONTH(Table1[[#This Row],[Reporting date]])<Pol_Inc_Month_Shifted,YEAR(Table1[[#This Row],[Reporting date]])-1,YEAR(Table1[[#This Row],[Reporting date]])) -> 2007 | AD20: =Table1[[#This Row],[Reporting year (shifted)]]-Table1[[#This Row],[Policy Year (shifted)]] -> 1
A21: Claim_9 | B21: Name_9 | C21: Public Liability Bodily Injury | D21: 39937 | E21: 39959 | F21: =IF(MONTH(Table1[[#This Row],[Loss date]])<Policy_Inception_Month,YEAR(Table1[[#This Row],[Loss date]])-1,YEAR(Table1[[#This Row],[Loss date]])) -> 2009 | G21: Slip,Trip Or Fall-Same Level | H21: GBP | I21: 674.55344 | J21: 0 | K21: 674.55344 | L21: 0 | M21: 0 | N21: 674.55344 | O21: =IF(Table1[[#This Row],[Overall amount]]=0,0,1) -> 1 | P21: =Table1[[#This Row],[Overall amount]]*Exchange_Rate -> 674.55344 | Q21: =Table1[[#This Row],[Overall (destination currency)]]*(1+Claims_Inflation)^((Revalue_at_date-Table1[[#This Row],[Loss date]])/365.25) -> 922.2 | R21: =INT(Table1[[#This Row],[Reporting date]])-INT(Table1[[#This Row],[Loss date]]) -> 22 | S21: Closed | T21: =VLOOKUP(Table1[[#This Row],[Policy Year]],exposure_table,3,FALSE) -> 760.22809 | U21: =IF(MONTH(Table1[[#This Row],[Reporting date]])<Policy_Inception_Month,YEAR(Table1[[#This Row],[Reporting date]])-1,YEAR(Table1[[#This Row],[Reporting date]])) -> 2009 | V21: =Table1[[#This Row],[Reporting year]]-Table1[[#This Row],[Policy Year]] -> 0 | W21: =INT(Table1[[#This Row],[Reporting date]])-INT(Table1[[#This Row],[Loss date]]) -> 22 | X21: =INT((YEAR(Table1[[#This Row],[Loss date]])*12+MONTH(Table1[[#This Row],[Loss date]])-Earliest_Month)/4) -> 12 | Y21: =INT((YEAR(Table1[[#This Row],[Reporting date]])*12+MONTH(Table1[[#This Row],[Reporting date]])-Earliest_Month)/4) -> 12 | Z21: =Table1[[#This Row],[Reporting third]]-Table1[[#This Row],[Policy third]] -> 0 | AA21: =IF(Table1[[#This Row],[Overall amount]]=0,"N/A",Table1[[#This Row],[Outstanding]]/Table1[[#This Row],[Overall amount]]) -> 0 | AB21: =IF(MONTH(Table1[[#This Row],[Loss date]])<Pol_Inc_Month_Shifted,YEAR(Table1[[#This Row],[Loss date]])-1,YEAR(Table1[[#This Row],[Loss date]])) -> 2008 | AC21: =IF(MONTH(Table1[[#This Row],[Reporting date]])<Pol_Inc_Month_Shifted,YEAR(Table1[[#This Row],[Reporting date]])-1,YEAR(Table1[[#This Row],[Reporting date]])) -> 2008 | AD21: =Table1[[#This Row],[Reporting year (shifted)]]-Table1[[#This Row],[Policy Year (shifted)]] -> 0
A22: Claim_10 | B22: Name_10 | C22: Public Liability Bodily Injury | D22: 40489 | E22: 40517 | F22: =IF(MONTH(Table1[[#This Row],[Loss date]])<Policy_Inception_Month,YEAR(Table1[[#This Row],[Loss date]])-1,YEAR(Table1[[#This Row],[Loss date]])) -> 2010 | G22: Slip,Trip Or Fall-Same Level | H22: GBP | I22: 3572.9845 | J22: 0 | K22: 3572.9845 | L22: 0 | M22: 0 | N22: 3572.9845 | O22: =IF(Table1[[#This Row],[Overall amount]]=0,0,1) -> 1 | P22: =Table1[[#This Row],[Overall amount]]*Exchange_Rate -> 3572.9845 | Q22: =Table1[[#This Row],[Overall (destination currency)]]*(1+Claims_Inflation)^((Revalue_at_date-Table1[[#This Row],[Loss date]])/365.25) -> 4537.5 | R22: =INT(Table1[[#This Row],[Reporting date]])-INT(Table1[[#This Row],[Loss date]]) -> 28 | S22: Closed | T22: =VLOOKUP(Table1[[#This Row],[Policy Year]],exposure_table,3,FALSE) -> 837.11514 | U22: =IF(MONTH(Table1[[#This Row],[Reporting date]])<Policy_Inception_Month,YEAR(Table1[[#This Row],[Reporting date]])-1,YEAR(Table1[[#This Row],[Reporting date]])) -> 2010 | V22: =Table1[[#This Row],[Reporting year]]-Table1[[#This Row],[Policy Year]] -> 0 | W22: =INT(Table1[[#This Row],[Reporting date]])-INT(Table1[[#This Row],[Loss date]]) -> 28 | X22: =INT((YEAR(Table1[[#This Row],[Loss date]])*12+MONTH(Table1[[#This Row],[Loss date]])-Earliest_Month)/4) -> 16 | Y22: =INT((YEAR(Table1[[#This Row],[Reporting date]])*12+MONTH(Table1[[#This Row],[Reporting date]])-Earliest_Month)/4) -> 17 | Z22: =Table1[[#This Row],[Reporting third]]-Table1[[#This Row],[Policy third]] -> 1 | AA22: =IF(Table1[[#This Row],[Overall amount]]=0,"N/A",Table1[[#This Row],[Outstanding]]/Table1[[#This Row],[Overall amount]]) -> 0 | AB22: =IF(MONTH(Table1[[#This Row],[Loss date]])<Pol_Inc_Month_Shifted,YEAR(Table1[[#This Row],[Loss date]])-1,YEAR(Table1[[#This Row],[Loss date]])) -> 2009 | AC22: =IF(MONTH(Table1[[#This Row],[Reporting date]])<Pol_Inc_Month_Shifted,YEAR(Table1[[#This Row],[Reporting date]])-1,YEAR(Table1[[#This Row],[Reporting date]])) -> 2010 | AD22: =Table1[[#This Row],[Reporting year (shifted)]]-Table1[[#This Row],[Policy Year (shifted)]] -> 1
A23: Claim_11 | B23: Name_11 | C23: Public Liability Bodily Injury | D23: 40421 | E23: 40557 | F23: =IF(MONTH(Table1[[#This Row],[Loss date]])<Policy_Inception_Month,YEAR(Table1[[#This Row],[Loss date]])-1,YEAR(Table1[[#This Row],[Loss date]])) -> 2010 | G23: Slip,Trip Or Fall-Same Level | H23: GBP | I23: 6885.4159 | J23: 0 | K23: 6885.4159 | L23: 0 | M23: 0 | N23: 6885.4159 | O23: =IF(Table1[[#This Row],[Overall amount]]=0,0,1) -> 1 | P23: =Table1[[#This Row],[Overall amount]]*Exchange_Rate -> 6885.4159 | Q23: =Table1[[#This Row],[Overall (destination currency)]]*(1+Claims_Inflation)^((Revalue_at_date-Table1[[#This Row],[Loss date]])/365.25) -> 8823.9 | R23: =INT(Table1[[#This Row],[Reporting date]])-INT(Table1[[#This Row],[Loss date]]) -> 136 | S23: Closed | T23: =VLOOKUP(Table1[[#This Row],[Policy Year]],exposure_table,3,FALSE) -> 837.11514 | U23: =IF(MONTH(Table1[[#This Row],[Reporting date]])<Policy_Inception_Month,YEAR(Table1[[#This Row],[Reporting date]])-1,YEAR(Table1[[#This Row],[Reporting date]])) -> 2010 | V23: =Table1[[#This Row],[Reporting year]]-Table1[[#This Row],[Policy Year]] -> 0 | W23: =INT(Table1[[#This Row],[Reporting date]])-INT(Table1[[#This Row],[Loss date]]) -> 136 | X23: =INT((YEAR(Table1[[#This Row],[Loss date]])*12+MONTH(Table1[[#This Row],[Loss date]])-Earliest_Month)/4) -> 16 | Y23: =INT((YEAR(Table1[[#This Row],[Reporting date]])*12+MONTH(Table1[[#This Row],[Reporting date]])-Earliest_Month)/4) -> 17 | Z23: =Table1[[#This Row],[Reporting third]]-Table1[[#This Row],[Policy third]] -> 1 | AA23: =IF(Table1[[#This Row],[Overall amount]]=0,"N/A",Table1[[#This Row],[Outstanding]]/Table1[[#This Row],[Overall amount]]) -> 0 | AB23: =IF(MONTH(Table1[[#This Row],[Loss date]])<Pol_Inc_Month_Shifted,YEAR(Table1[[#This Row],[Loss date]])-1,YEAR(Table1[[#This Row],[Loss date]])) -> 2009 | AC23: =IF(MONTH(Table1[[#This Row],[Reporting date]])<Pol_Inc_Month_Shifted,YEAR(Table1[[#This Row],[Reporting date]])-1,YEAR(Table1[[#This Row],[Reporting date]])) -> 2010 | AD23: =Table1[[#This Row],[Reporting year (shifted)]]-Table1[[#This Row],[Policy Year (shifted)]] -> 1
A24: Claim_12 | B24: Name_12 | C24: Public Liability Property Damage | D24: 39368 | E24: 39451 | F24: =IF(MONTH(Table1[[#This Row],[Loss date]])<Policy_Inception_Month,YEAR(Table1[[#This Row],[Loss date]])-1,YEAR(Table1[[#This Row],[Loss date]])) -> 2007 | G24: Contact With | H24: GBP | I24: 3893.5168 | J24: 0 | K24: 3893.5168 | L24: 0 | M24: 0 | N24: 3893.5168 | O24: =IF(Table1[[#This Row],[Overall amount]]=0,0,1) -> 1 | P24: =Table1[[#This Row],[Overall amount]]*Exchange_Rate -> 3893.5168 | Q24: =Table1[[#This Row],[Overall (destination currency)]]*(1+Claims_Inflation)^((Revalue_at_date-Table1[[#This Row],[Loss date]])/365.25) -> 5743.284 | R24: =INT(Table1[[#This Row],[Reporting date]])-INT(Table1[[#This Row],[Loss date]]) -> 83 | S24: Closed | T24: =VLOOKUP(Table1[[#This Row],[Policy Year]],exposure_table,3,FALSE) -> 547.77364 | U24: =IF(MONTH(Table1[[#This Row],[Reporting date]])<Policy_Inception_Month,YEAR(Table1[[#This Row],[Reporting date]])-1,YEAR(Table1[[#This Row],[Reporting date]])) -> 2007 | V24: =Table1[[#This Row],[Reporting year]]-Table1[[#This Row],[Policy Year]] -> 0 | W24: =INT(Table1[[#This Row],[Reporting date]])-INT(Table1[[#This Row],[Loss date]]) -> 83 | X24: =INT((YEAR(Table1[[#This Row],[Loss date]])*12+MONTH(Table1[[#This Row],[Loss date]])-Earliest_Month)/4) -> 7 | Y24: =INT((YEAR(Table1[[#This Row],[Reporting date]])*12+MONTH(Table1[[#This Row],[Reporting date]])-Earliest_Month)/4) -> 8 | Z24: =Table1[[#This Row],[Reporting third]]-Table1[[#This Row],[Policy third]] -> 1 | AA24: =IF(Table1[[#This Row],[Overall amount]]=0,"N/A",Table1[[#This Row],[Outstanding]]/Table1[[#This Row],[Overall amount]]) -> 0 | AB24: =IF(MONTH(Table1[[#This Row],[Loss date]])<Pol_Inc_Month_Shifted,YEAR(Table1[[#This Row],[Loss date]])-1,YEAR(Table1[[#This Row],[Loss date]])) -> 2006 | AC24: =IF(MONTH(Table1[[#This Row],[Reporting date]])<Pol_Inc_Month_Shifted,YEAR(Table1[[#This Row],[Reporting date]])-1,YEAR(Table1[[#This Row],[Reporting date]])) -> 2007 | AD24: =Table1[[#This Row],[Reporting year (shifted)]]-Table1[[#This Row],[Policy Year (shifted)]] -> 1
A25: Claim_13 | B25: Name_13 | C25: Public Liability Property Damage | D25: 39089 | E25: 39192 | F25: =IF(MONTH(Table1[[#This Row],[Loss date]])<Policy_Inception_Month,YEAR(Table1[[#This Row],[Loss date]])-1,YEAR(Table1[[#This Row],[Loss date]])) -> 2006 | G25: Contact With | H25: GBP | I25: 482.98571 | J25: 0 | K25: 482.98571 | L25: 0 | M25: 7.2447856 | N25: 475.74092 | O25: =IF(Table1[[#This Row],[Overall amount]]=0,0,1) -> 1 | P25: =Table1[[#This Row],[Overall amount]]*Exchange_Rate -> 475.74092 | Q25: =Table1[[#This Row],[Overall (destination currency)]]*(1+Claims_Inflation)^((Revalue_at_date-Table1[[#This Row],[Loss date]])/365.25) -> 728.4075 | R25: =INT(Table1[[#This Row],[Reporting date]])-INT(Table1[[#This Row],[Loss date]]) -> 103 | S25: Closed | T25: =VLOOKUP(Table1[[#This Row],[Policy Year]],exposure_table,3,FALSE) -> 483.32023 | U25: =IF(MONTH(Table1[[#This Row],[Reporting date]])<Policy_Inception_Month,YEAR(Table1[[#This Row],[Reporting date]])-1,YEAR(Table1[[#This Row],[Reporting date]])) -> 2007 | V25: =Table1[[#This Row],[Reporting year]]-Table1[[#This Row],[Policy Year]] -> 1 | W25: =INT(Table1[[#This Row],[Reporting date]])-INT(Table1[[#This Row],[Loss date]]) -> 103 | X25: =INT((YEAR(Table1[[#This Row],[Loss date]])*12+MONTH(Table1[[#This Row],[Loss date]])-Earliest_Month)/4) -> 5 | Y25: =INT((YEAR(Table1[[#This Row],[Reporting date]])*12+MONTH(Table1[[#This Row],[Reporting date]])-Earliest_Month)/4) -> 6 | Z25: =Table1[[#This Row],[Reporting third]]-Table1[[#This Row],[Policy third]] -> 1 | AA25: =IF(Table1[[#This Row],[Overall amount]]=0,"N/A",Table1[[#This Row],[Outstanding]]/Table1[[#This Row],[Overall amount]]) -> 0 | AB25: =IF(MONTH(Table1[[#This Row],[Loss date]])<Pol_Inc_Month_Shifted,YEAR(Table1[[#This Row],[Loss date]])-1,YEAR(Table1[[#This Row],[Loss date]])) -> 2006 | AC25: =IF(MONTH(Table1[[#This Row],[Reporting date]])<Pol_Inc_Month_Shifted,YEAR(Table1[[#This Row],[Reporting date]])-1,YEAR(Table1[[#This Row],[Reporting date]])) -> 2006 | AD25: =Table1[[#This Row],[Reporting year (shifted)]]-Table1[[#This Row],[Policy Year (shifted)]] -> 0
... A1730: Claim_1718 | B1730: Name_1718 | C1730: Public Liability Property Damage | D1730: 41677 | E1730: 41684 | F1730: =IF(MONTH(Table1[[#This Row],[Loss date]])<Policy_Inception_Month,YEAR(Table1[[#This Row],[Loss date]])-1,YEAR(Table1[[#This Row],[Loss date]])) -> 2013 | G1730: Property Damage | H1730: GBP | I1730: 0 | J1730: 0 | K1730: 0 | L1730: 0 | M1730: 0 | N1730: 0 | O1730: =IF(Table1[[#This Row],[Overall amount]]=0,0,1) -> 0 | P1730: =Table1[[#This Row],[Overall amount]]*Exchange_Rate -> 0 | Q1730: =Table1[[#This Row],[Overall (destination currency)]]*(1+Claims_Inflation)^((Revalue_at_date-Table1[[#This Row],[Loss date]])/365.25) -> 0 | R1730: =INT(Table1[[#This Row],[Reporting date]])-INT(Table1[[#This Row],[Loss date]]) -> 7 | S1730: Closed | T1730: =VLOOKUP(Table1[[#This Row],[Policy Year]],exposure_table,3,FALSE) -> 1090.5865 | U1730: =IF(MONTH(Table1[[#This Row],[Reporting date]])<Policy_Inception_Month,YEAR(Table1[[#This Row],[Reporting date]])-1,YEAR(Table1[[#This Row],[Reporting date]])) -> 2013 | V1730: =Table1[[#This Row],[Reporting year]]-Table1[[#This Row],[Policy Year]] -> 0 | W1730: =INT(Table1[[#This Row],[Reporting date]])-INT(Table1[[#This Row],[Loss date]]) -> 7 | X1730: =INT((YEAR(Table1[[#This Row],[Loss date]])*12+MONTH(Table1[[#This Row],[Loss date]])-Earliest_Month)/4) -> 26 | Y1730: =INT((YEAR(Table1[[#This Row],[Reporting date]])*12+MONTH(Table1[[#This Row],[Reporting date]])-Earliest_Month)/4) -> 26 | Z1730: =Table1[[#This Row],[Reporting third]]-Table1[[#This Row],[Policy third]] -> 0 | AA1730: =IF(Table1[[#This Row],[Overall amount]]=0,"N/A",Table1[[#This Row],[Outstanding]]/Table1[[#This Row],[Overall amount]]) -> N/A | AB1730: =IF(MONTH(Table1[[#This Row],[Loss date]])<Pol_Inc_Month_Shifted,YEAR(Table1[[#This Row],[Loss date]])-1,YEAR(Table1[[#This Row],[Loss date]])) -> 2013 | AC1730: =IF(MONTH(Table1[[#This Row],[Reporting date]])<Pol_Inc_Month_Shifted,YEAR(Table1[[#This Row],[Reporting date]])-1,YEAR(Table1[[#This Row],[Reporting date]])) -> 2013 | AD1730: =Table1[[#This Row],[Reporting year (shifted)]]-Table1[[#This Row],[Policy Year (shifted)]] -> 0

Sheet 3. Projection - Methods 1 and 2
A1: 由于存在最后一年的数据不完整情况，这里展示了四种预测IBNR案件数的方法
A4: METHOD 2 - GROSS UP LAST DIAGONAL | N4: METHOD 1 - IGNORE LAST DIAGONAL
A7: 1 - Original table | N7: 1 - Original table
F9: Delay (years)
A10: Policy year | B10: 0 | C10: 1 | D10: 2 | E10: 3 | F10: 4 | G10: 5 | H10: 6 | I10: 7 | J10: 8 | K10: 9 | N10: See table on the left
A11: =Earliest_Year -> 2005 | B11: =IF($A11+B$10>Latest_Year,"",SUMIFS(Table1[Non-zero? (1=Yes)],Table1[Policy Year],"="&'3. Projection - Methods 1 and 2'!$A11,Table1[Delay (years)],"="&'3. Projection - Methods 1 and 2'!B$10)) -> 50 | C11: =IF($A11+C$10>Latest_Year,"",SUMIFS(Table1[Non-zero? (1=Yes)],Table1[Policy Year],"="&'3. Projection - Methods 1 and 2'!$A11,Table1[Delay (years)],"="&'3. Projection - Methods 1 and 2'!C$10)) -> 26 | D11: =IF($A11+D$10>Latest_Year,"",SUMIFS(Table1[Non-zero? (1=Yes)],Table1[Policy Year],"="&'3. Projection - Methods 1 and 2'!$A11,Table1[Delay (years)],"="&'3. Projection - Methods 1 and 2'!D$10)) -> 5 | E11: =IF($A11+E$10>Latest_Year,"",SUMIFS(Table1[Non-zero? (1=Yes)],Table1[Policy Year],"="&'3. Projection - Methods 1 and 2'!$A11,Table1[Delay (years)],"="&'3. Projection - Methods 1 and 2'!E$10)) -> 3 | F11: =IF($A11+F$10>Latest_Year,"",SUMIFS(Table1[Non-zero? (1=Yes)],Table1[Policy Year],"="&'3. Projection - Methods 1 and 2'!$A11,Table1[Delay (years)],"="&'3. Projection - Methods 1 and 2'!F$10)) -> 2 | G11: =IF($A11+G$10>Latest_Year,"",SUMIFS(Table1[Non-zero? (1=Yes)],Table1[Policy Year],"="&'3. Projection - Methods 1 and 2'!$A11,Table1[Delay (years)],"="&'3. Projection - Methods 1 and 2'!G$10)) -> 0 | H11: =IF($A11+H$10>Latest_Year,"",SUMIFS(Table1[Non-zero? (1=Yes)],Table1[Policy Year],"="&'3. Projection - Methods 1 and 2'!$A11,Table1[Delay (years)],"="&'3. Projection - Methods 1 and 2'!H$10)) -> 0 | I11: =IF($A11+I$10>Latest_Year,"",SUMIFS(Table1[Non-zero? (1=Yes)],Table1[Policy Year],"="&'3. Projection - Methods 1 and 2'!$A11,Table1[Delay (years)],"="&'3. Projection - Methods 1 and 2'!I$10)) -> 0 | ... K11: =IF($A11+K$10>Latest_Year,"",SUMIFS(Table1[Non-zero? (1=Yes)],Table1[Policy Year],"="&'3. Projection - Methods 1 and 2'!$A11,Table1[Delay (years)],"="&'3. Projection - Methods 1 and 2'!K$10)) -> 0
A12: =A11+1 -> 2006 | B12: =IF($A12+B$10>Latest_Year,"",SUMIFS(Table1[Non-zero? (1=Yes)],Table1[Policy Year],"="&'3. Projection - Methods 1 and 2'!$A12,Table1[Delay (years)],"="&'3. Projection - Methods 1 and 2'!B$10)) -> 41 | C12: =IF($A12+C$10>Latest_Year,"",SUMIFS(Table1[Non-zero? (1=Yes)],Table1[Policy Year],"="&'3. Projection - Methods 1 and 2'!$A12,Table1[Delay (years)],"="&'3. Projection - Methods 1 and 2'!C$10)) -> 28 | D12: =IF($A12+D$10>Latest_Year,"",SUMIFS(Table1[Non-zero? (1=Yes)],Table1[Policy Year],"="&'3. Projection - Methods 1 and 2'!$A12,Table1[Delay (years)],"="&'3. Projection - Methods 1 and 2'!D$10)) -> 13 | E12: =IF($A12+E$10>Latest_Year,"",SUMIFS(Table1[Non-zero? (1=Yes)],Table1[Policy Year],"="&'3. Projection - Methods 1 and 2'!$A12,Table1[Delay (years)],"="&'3. Projection - Methods 1 and 2'!E$10)) -> 6 | F12: =IF($A12+F$10>Latest_Year,"",SUMIFS(Table1[Non-zero? (1=Yes)],Table1[Policy Year],"="&'3. Projection - Methods 1 and 2'!$A12,Table1[Delay (years)],"="&'3. Projection - Methods 1 and 2'!F$10)) -> 4 | G12: =IF($A12+G$10>Latest_Year,"",SUMIFS(Table1[Non-zero? (1=Yes)],Table1[Policy Year],"="&'3. Projection - Methods 1 and 2'!$A12,Table1[Delay (years)],"="&'3. Projection - Methods 1 and 2'!G$10)) -> 0 | H12: =IF($A12+H$10>Latest_Year,"",SUMIFS(Table1[Non-zero? (1=Yes)],Table1[Policy Year],"="&'3. Projection - Methods 1 and 2'!$A12,Table1[Delay (years)],"="&'3. Projection - Methods 1 and 2'!H$10)) -> 0 | I12: =IF($A12+I$10>Latest_Year,"",SUMIFS(Table1[Non-zero? (1=Yes)],Table1[Policy Year],"="&'3. Projection - Methods 1 and 2'!$A12,Table1[Delay (years)],"="&'3. Projection - Methods 1 and 2'!I$10)) -> 0 | ... K12: =IF($A12+K$10>Latest_Year,"",SUMIFS(Table1[Non-zero? (1=Yes)],Table1[Policy Year],"="&'3. Projection - Methods 1 and 2'!$A12,Table1[Delay (years)],"="&'3. Projection - Methods 1 and 2'!K$10))
A13: =A12+1 -> 2007 | B13: =IF($A13+B$10>Latest_Year,"",SUMIFS(Table1[Non-zero? (1=Yes)],Table1[Policy Year],"="&'3. Projection - Methods 1 and 2'!$A13,Table1[Delay (years)],"="&'3. Projection - Methods 1 and 2'!B$10)) -> 65 | C13: =IF($A13+C$10>Latest_Year,"",SUMIFS(Table1[Non-zero? (1=Yes)],Table1[Policy Year],"="&'3. Projection - Methods 1 and 2'!$A13,Table1[Delay (years)],"="&'3. Projection - Methods 1 and 2'!C$10)) -> 33 | D13: =IF($A13+D$10>Latest_Year,"",SUMIFS(Table1[Non-zero? (1=Yes)],Table1[Policy Year],"="&'3. Projection - Methods 1 and 2'!$A13,Table1[Delay (years)],"="&'3. Projection - Methods 1 and 2'!D$10)) -> 10 | E13: =IF($A13+E$10>Latest_Year,"",SUMIFS(Table1[Non-zero? (1=Yes)],Table1[Policy Year],"="&'3. Projection - Methods 1 and 2'!$A13,Table1[Delay (years)],"="&'3. Projection - Methods 1 and 2'!E$10)) -> 2 | F13: =IF($A13+F$10>Latest_Year,"",SUMIFS(Table1[Non-zero? (1=Yes)],Table1[Policy Year],"="&'3. Projection - Methods 1 and 2'!$A13,Table1[Delay (years)],"="&'3. Projection - Methods 1 and 2'!F$10)) -> 0 | G13: =IF($A13+G$10>Latest_Year,"",SUMIFS(Table1[Non-zero? (1=Yes)],Table1[Policy Year],"="&'3. Projection - Methods 1 and 2'!$A13,Table1[Delay (years)],"="&'3. Projection - Methods 1 and 2'!G$10)) -> 0 | H13: =IF($A13+H$10>Latest_Year,"",SUMIFS(Table1[Non-zero? (1=Yes)],Table1[Policy Year],"="&'3. Projection - Methods 1 and 2'!$A13,Table1[Delay (years)],"="&'3. Projection - Methods 1 and 2'!H$10)) -> 0 | I13: =IF($A13+I$10>Latest_Year,"",SUMIFS(Table1[Non-zero? (1=Yes)],Table1[Policy Year],"="&'3. Projection - Methods 1 and 2'!$A13,Table1[Delay (years)],"="&'3. Projection - Methods 1 and 2'!I$10)) -> 0 | ... K13: =IF($A13+K$10>Latest_Year,"",SUMIFS(Table1[Non-zero? (1=Yes)],Table1[Policy Year],"="&'3. Projection - Methods 1 and 2'!$A13,Table1[Delay (years)],"="&'3. Projection - Methods 1 and 2'!K$10))
A14: =A13+1 -> 2008 | B14: =IF($A14+B$10>Latest_Year,"",SUMIFS(Table1[Non-zero? (1=Yes)],Table1[Policy Year],"="&'3. Projection - Methods 1 and 2'!$A14,Table1[Delay (years)],"="&'3. Projection - Methods 1 and 2'!B$10)) -> 83 | C14: =IF($A14+C$10>Latest_Year,"",SUMIFS(Table1[Non-zero? (1=Yes)],Table1[Policy Year],"="&'3. Projection - Methods 1 and 2'!$A14,Table1[Delay (years)],"="&'3. Projection - Methods 1 and 2'!C$10)) -> 47 | D14: =IF($A14+D$10>Latest_Year,"",SUMIFS(Table1[Non-zero? (1=Yes)],Table1[Policy Year],"="&'3. Projection - Methods 1 and 2'!$A14,Table1[Delay (years)],"="&'3. Projection - Methods 1 and 2'!D$10)) -> 8 | E14: =IF($A14+E$10>Latest_Year,"",SUMIFS(Table1[Non-zero? (1=Yes)],Table1[Policy Year],"="&'3. Projection - Methods 1 and 2'!$A14,Table1[Delay (years)],"="&'3. Projection - Methods 1 and 2'!E$10)) -> 6 | F14: =IF($A14+F$10>Latest_Year,"",SUMIFS(Table1[Non-zero? (1=Yes)],Table1[Policy Year],"="&'3. Projection - Methods 1 and 2'!$A14,Table1[Delay (years)],"="&'3. Projection - Methods 1 and 2'!F$10)) -> 1 | G14: =IF($A14+G$10>Latest_Year,"",SUMIFS(Table1[Non-zero? (1=Yes)],Table1[Policy Year],"="&'3. Projection - Methods 1 and 2'!$A14,Table1[Delay (years)],"="&'3. Projection - Methods 1 and 2'!G$10)) -> 0 | H14: =IF($A14+H$10>Latest_Year,"",SUMIFS(Table1[Non-zero? (1=Yes)],Table1[Policy Year],"="&'3. Projection - Methods 1 and 2'!$A14,Table1[Delay (years)],"="&'3. Projection - Methods 1 and 2'!H$10)) -> 1 | I14: =IF($A14+I$10>Latest_Year,"",SUMIFS(Table1[Non-zero? (1=Yes)],Table1[Policy Year],"="&'3. Projection - Methods 1 and 2'!$A14,Table1[Delay (years)],"="&'3. Projection - Methods 1 and 2'!I$10)) | ... K14: =IF($A14+K$10>Latest_Year,"",SUMIFS(Table1[Non-zero? (1=Yes)],Table1[Policy Year],"="&'3. Projection - Methods 1 and 2'!$A14,Table1[Delay (years)],"="&'3. Projection - Methods 1 and 2'!K$10))
A15: =A14+1 -> 2009 | B15: =IF($A15+B$10>Latest_Year,"",SUMIFS(Table1[Non-zero? (1=Yes)],Table1[Policy Year],"="&'3. Projection - Methods 1 and 2'!$A15,Table1[Delay (years)],"="&'3. Projection - Methods 1 and 2'!B$10)) -> 120 | C15: =IF($A15+C$10>Latest_Year,"",SUMIFS(Table1[Non-zero? (1=Yes)],Table1[Policy Year],"="&'3. Projection - Methods 1 and 2'!$A15,Table1[Delay (years)],"="&'3. Projection - Methods 1 and 2'!C$10)) -> 45 | D15: =IF($A15+D$10>Latest_Year,"",SUMIFS(Table1[Non-zero? (1=Yes)],Table1[Policy Year],"="&'3. Projection - Methods 1 and 2'!$A15,Table1[Delay (years)],"="&'3. Projection - Methods 1 and 2'!D$10)) -> 16 | E15: =IF($A15+E$10>Latest_Year,"",SUMIFS(Table1[Non-zero? (1=Yes)],Table1[Policy Year],"="&'3. Projection - Methods 1 and 2'!$A15,Table1[Delay (years)],"="&'3. Projection - Methods 1 and 2'!E$10)) -> 9 | F15: =IF($A15+F$10>Latest_Year,"",SUMIFS(Table1[Non-zero? (1=Yes)],Table1[Policy Year],"="&'3. Projection - Methods 1 and 2'!$A15,Table1[Delay (years)],"="&'3. Projection - Methods 1 and 2'!F$10)) -> 2 | G15: =IF($A15+G$10>Latest_Year,"",SUMIFS(Table1[Non-zero? (1=Yes)],Table1[Policy Year],"="&'3. Projection - Methods 1 and 2'!$A15,Table1[Delay (years)],"="&'3. Projection - Methods 1 and 2'!G$10)) -> 2 | H15: =IF($A15+H$10>Latest_Year,"",SUMIFS(Table1[Non-zero? (1=Yes)],Table1[Policy Year],"="&'3. Projection - Methods 1 and 2'!$A15,Table1[Delay (years)],"="&'3. Projection - Methods 1 and 2'!H$10)) | I15: =IF($A15+I$10>Latest_Year,"",SUMIFS(Table1[Non-zero? (1=Yes)],Table1[Policy Year],"="&'3. Projection - Methods 1 and 2'!$A15,Table1[Delay (years)],"="&'3. Projection - Methods 1 and 2'!I$10)) | ... K15: =IF($A15+K$10>Latest_Year,"",SUMIFS(Table1[Non-zero? (1=Yes)],Table1[Policy Year],"="&'3. Projection - Methods 1 and 2'!$A15,Table1[Delay (years)],"="&'3. Projection - Methods 1 and 2'!K$10))
A16: =A15+1 -> 2010 | B16: =IF($A16+B$10>Latest_Year,"",SUMIFS(Table1[Non-zero? (1=Yes)],Table1[Policy Year],"="&'3. Projection - Methods 1 and 2'!$A16,Table1[Delay (years)],"="&'3. Projection - Methods 1 and 2'!B$10)) -> 149 | C16: =IF($A16+C$10>Latest_Year,"",SUMIFS(Table1[Non-zero? (1=Yes)],Table1[Policy Year],"="&'3. Projection - Methods 1 and 2'!$A16,Table1[Delay (years)],"="&'3. Projection - Methods 1 and 2'!C$10)) -> 77 | D16: =IF($A16+D$10>Latest_Year,"",SUMIFS(Table1[Non-zero? (1=Yes)],Table1[Policy Year],"="&'3. Projection - Methods 1 and 2'!$A16,Table1[Delay (years)],"="&'3. Projection - Methods 1 and 2'!D$10)) -> 20 | E16: =IF($A16+E$10>Latest_Year,"",SUMIFS(Table1[Non-zero? (1=Yes)],Table1[Policy Year],"="&'3. Projection - Methods 1 and 2'!$A16,Table1[Delay (years)],"="&'3. Projection - Methods 1 and 2'!E$10)) -> 7 | F16: =IF($A16+F$10>Latest_Year,"",SUMIFS(Table1[Non-zero? (1=Yes)],Table1[Policy Year],"="&'3. Projection - Methods 1 and 2'!$A16,Table1[Delay (years)],"="&'3. Projection - Methods 1 and 2'!F$10)) -> 3 | G16: =IF($A16+G$10>Latest_Year,"",SUMIFS(Table1[Non-zero? (1=Yes)],Table1[Policy Year],"="&'3. Projection - Methods 1 and 2'!$A16,Table1[Delay (years)],"="&'3. Projection - Methods 1 and 2'!G$10)) | H16: =IF($A16+H$10>Latest_Year,"",SUMIFS(Table1[Non-zero? (1=Yes)],Table1[Policy Year],"="&'3. Projection - Methods 1 and 2'!$A16,Table1[Delay (years)],"="&'3. Projection - Methods 1 and 2'!H$10)) | I16: =IF($A16+I$10>Latest_Year,"",SUMIFS(Table1[Non-zero? (1=Yes)],Table1[Policy Year],"="&'3. Projection - Methods 1 and 2'!$A16,Table1[Delay (years)],"="&'3. Projection - Methods 1 and 2'!I$10)) | ... K16: =IF($A16+K$10>Latest_Year,"",SUMIFS(Table1[Non-zero? (1=Yes)],Table1[Policy Year],"="&'3. Projection - Methods 1 and 2'!$A16,Table1[Delay (years)],"="&'3. Projection - Methods 1 and 2'!K$10))
A17: =A16+1 -> 2011 | B17: =IF($A17+B$10>Latest_Year,"",SUMIFS(Table1[Non-zero? (1=Yes)],Table1[Policy Year],"="&'3. Projection - Methods 1 and 2'!$A17,Table1[Delay (years)],"="&'3. Projection - Methods 1 and 2'!B$10)) -> 158 | C17: =IF($A17+C$10>Latest_Year,"",SUMIFS(Table1[Non-zero? (1=Yes)],Table1[Policy Year],"="&'3. Projection - Methods 1 and 2'!$A17,Table1[Delay (years)],"="&'3. Projection - Methods 1 and 2'!C$10)) -> 64 | D17: =IF($A17+D$10>Latest_Year,"",SUMIFS(Table1[Non-zero? (1=Yes)],Table1[Policy Year],"="&'3. Projection - Methods 1 and 2'!$A17,Table1[Delay (years)],"="&'3. Projection - Methods 1 and 2'!D$10)) -> 19 | E17: =IF($A17+E$10>Latest_Year,"",SUMIFS(Table1[Non-zero? (1=Yes)],Table1[Policy Year],"="&'3. Projection - Methods 1 and 2'!$A17,Table1[Delay (years)],"="&'3. Projection - Methods 1 and 2'!E$10)) -> 9 | F17: =IF($A17+F$10>Latest_Year,"",SUMIFS(Table1[Non-zero? (1=Yes)],Table1[Policy Year],"="&'3. Projection - Methods 1 and 2'!$A17,Table1[Delay (years)],"="&'3. Projection - Methods 1 and 2'!F$10)) | G17: =IF($A17+G$10>Latest_Year,"",SUMIFS(Table1[Non-zero? (1=Yes)],Table1[Policy Year],"="&'3. Projection - Methods 1 and 2'!$A17,Table1[Delay (years)],"="&'3. Projection - Methods 1 and 2'!G$10)) | H17: =IF($A17+H$10>Latest_Year,"",SUMIFS(Table1[Non-zero? (1=Yes)],Table1[Policy Year],"="&'3. Projection - Methods 1 and 2'!$A17,Table1[Delay (years)],"="&'3. Projection - Methods 1 and 2'!H$10)) | I17: =IF($A17+I$10>Latest_Year,"",SUMIFS(Table1[Non-zero? (1=Yes)],Table1[Policy Year],"="&'3. Projection - Methods 1 and 2'!$A17,Table1[Delay (years)],"="&'3. Projection - Methods 1 and 2'!I$10)) | ... K17: =IF($A17+K$10>Latest_Year,"",SUMIFS(Table1[Non-zero? (1=Yes)],Table1[Policy Year],"="&'3. Projection - Methods 1 and 2'!$A17,Table1[Delay (years)],"="&'3. Projection - Methods 1 and 2'!K$10))
A18: =A17+1 -> 2012 | B18: =IF($A18+B$10>Latest_Year,"",SUMIFS(Table1[Non-zero? (1=Yes)],Table1[Policy Year],"="&'3. Projection - Methods 1 and 2'!$A18,Table1[Delay (years)],"="&'3. Projection - Methods 1 and 2'!B$10)) -> 96 | C18: =IF($A18+C$10>Latest_Year,"",SUMIFS(Table1[Non-zero? (1=Yes)],Table1[Policy Year],"="&'3. Projection - Methods 1 and 2'!$A18,Table1[Delay (years)],"="&'3. Projection - Methods 1 and 2'!C$10)) -> 81 | D18: =IF($A18+D$10>Latest_Year,"",SUMIFS(Table1[Non-zero? (1=Yes)],Table1[Policy Year],"="&'3. Projection - Methods 1 and 2'!$A18,Table1[Delay (years)],"="&'3. Projection - Methods 1 and 2'!D$10)) -> 22 | E18: =IF($A18+E$10>Latest_Year,"",SUMIFS(Table1[Non-zero? (1=Yes)],Table1[Policy Year],"="&'3. Projection - Methods 1 and 2'!$A18,Table1[Delay (years)],"="&'3. Projection - Methods 1 and 2'!E$10)) | F18: =IF($A18+F$10>Latest_Year,"",SUMIFS(Table1[Non-zero? (1=Yes)],Table1[Policy Year],"="&'3. Projection - Methods 1 and 2'!$A18,Table1[Delay (years)],"="&'3. Projection - Methods 1 and 2'!F$10)) | G18: =IF($A18+G$10>Latest_Year,"",SUMIFS(Table1[Non-zero? (1=Yes)],Table1[Policy Year],"="&'3. Projection - Methods 1 and 2'!$A18,Table1[Delay (years)],"="&'3. Projection - Methods 1 and 2'!G$10)) | H18: =IF($A18+H$10>Latest_Year,"",SUMIFS(Table1[Non-zero? (1=Yes)],Table1[Policy Year],"="&'3. Projection - Methods 1 and 2'!$A18,Table1[Delay (years)],"="&'3. Projection - Methods 1 and 2'!H$10)) | I18: =IF($A18+I$10>Latest_Year,"",SUMIFS(Table1[Non-zero? (1=Yes)],Table1[Policy Year],"="&'3. Projection - Methods 1 and 2'!$A18,Table1[Delay (years)],"="&'3. Projection - Methods 1 and 2'!I$10)) | ... K18: =IF($A18+K$10>Latest_Year,"",SUMIFS(Table1[Non-zero? (1=Yes)],Table1[Policy Year],"="&'3. Projection - Methods 1 and 2'!$A18,Table1[Delay (years)],"="&'3. Projection - Methods 1 and 2'!K$10))
A19: =A18+1 -> 2013 | B19: =IF($A19+B$10>Latest_Year,"",SUMIFS(Table1[Non-zero? (1=Yes)],Table1[Policy Year],"="&'3. Projection - Methods 1 and 2'!$A19,Table1[Delay (years)],"="&'3. Projection - Methods 1 and 2'!B$10)) -> 102 | C19: =IF($A19+C$10>Latest_Year,"",SUMIFS(Table1[Non-zero? (1=Yes)],Table1[Policy Year],"="&'3. Projection - Methods 1 and 2'!$A19,Table1[Delay (years)],"="&'3. Projection - Methods 1 and 2'!C$10)) -> 99 | D19: =IF($A19+D$10>Latest_Year,"",SUMIFS(Table1[Non-zero? (1=Yes)],Table1[Policy Year],"="&'3. Projection - Methods 1 and 2'!$A19,Table1[Delay (years)],"="&'3. Projection - Methods 1 and 2'!D$10)) | E19: =IF($A19+E$10>Latest_Year,"",SUMIFS(Table1[Non-zero? (1=Yes)],Table1[Policy Year],"="&'3. Projection - Methods 1 and 2'!$A19,Table1[Delay (years)],"="&'3. Projection - Methods 1 and 2'!E$10)) | F19: =IF($A19+F$10>Latest_Year,"",SUMIFS(Table1[Non-zero? (1=Yes)],Table1[Policy Year],"="&'3. Projection - Methods 1 and 2'!$A19,Table1[Delay (years)],"="&'3. Projection - Methods 1 and 2'!F$10)) | G19: =IF($A19+G$10>Latest_Year,"",SUMIFS(Table1[Non-zero? (1=Yes)],Table1[Policy Year],"="&'3. Projection - Methods 1 and 2'!$A19,Table1[Delay (years)],"="&'3. Projection - Methods 1 and 2'!G$10)) | H19: =IF($A19+H$10>Latest_Year,"",SUMIFS(Table1[Non-zero? (1=Yes)],Table1[Policy Year],"="&'3. Projection - Methods 1 and 2'!$A19,Table1[Delay (years)],"="&'3. Projection - Methods 1 and 2'!H$10)) | I19: =IF($A19+I$10>Latest_Year,"",SUMIFS(Table1[Non-zero? (1=Yes)],Table1[Policy Year],"="&'3. Projection - Methods 1 and 2'!$A19,Table1[Delay (years)],"="&'3. Projection - Methods 1 and 2'!I$10)) | ... K19: =IF($A19+K$10>Latest_Year,"",SUMIFS(Table1[Non-zero? (1=Yes)],Table1[Policy Year],"="&'3. Projection - Methods 1 and 2'!$A19,Table1[Delay (years)],"="&'3. Projection - Methods 1 and 2'!K$10))
A20: =A19+1 -> 2014 | B20: =IF($A20+B$10>Latest_Year,"",SUMIFS(Table1[Non-zero? (1=Yes)],Table1[Policy Year],"="&'3. Projection - Methods 1 and 2'!$A20,Table1[Delay (years)],"="&'3. Projection - Methods 1 and 2'!B$10)) -> 68 | C20: =IF($A20+C$10>Latest_Year,"",SUMIFS(Table1[Non-zero? (1=Yes)],Table1[Policy Year],"="&'3. Projection - Methods 1 and 2'!$A20,Table1[Delay (years)],"="&'3. Projection - Methods 1 and 2'!C$10)) | D20: =IF($A20+D$10>Latest_Year,"",SUMIFS(Table1[Non-zero? (1=Yes)],Table1[Policy Year],"="&'3. Projection - Methods 1 and 2'!$A20,Table1[Delay (years)],"="&'3. Projection - Methods 1 and 2'!D$10)) | E20: =IF($A20+E$10>Latest_Year,"",SUMIFS(Table1[Non-zero? (1=Yes)],Table1[Policy Year],"="&'3. Projection - Methods 1 and 2'!$A20,Table1[Delay (years)],"="&'3. Projection - Methods 1 and 2'!E$10)) | F20: =IF($A20+F$10>Latest_Year,"",SUMIFS(Table1[Non-zero? (1=Yes)],Table1[Policy Year],"="&'3. Projection - Methods 1 and 2'!$A20,Table1[Delay (years)],"="&'3. Projection - Methods 1 and 2'!F$10)) | G20: =IF($A20+G$10>Latest_Year,"",SUMIFS(Table1[Non-zero? (1=Yes)],Table1[Policy Year],"="&'3. Projection - Methods 1 and 2'!$A20,Table1[Delay (years)],"="&'3. Projection - Methods 1 and 2'!G$10)) | H20: =IF($A20+H$10>Latest_Year,"",SUMIFS(Table1[Non-zero? (1=Yes)],Table1[Policy Year],"="&'3. Projection - Methods 1 and 2'!$A20,Table1[Delay (years)],"="&'3. Projection - Methods 1 and 2'!H$10)) | I20: =IF($A20+I$10>Latest_Year,"",SUMIFS(Table1[Non-zero? (1=Yes)],Table1[Policy Year],"="&'3. Projection - Methods 1 and 2'!$A20,Table1[Delay (years)],"="&'3. Projection - Methods 1 and 2'!I$10)) | ... K20: =IF($A20+K$10>Latest_Year,"",SUMIFS(Table1[Non-zero? (1=Yes)],Table1[Policy Year],"="&'3. Projection - Methods 1 and 2'!$A20,Table1[Delay (years)],"="&'3. Projection - Methods 1 and 2'!K$10))
A23: 2 - Cumulative | N23: 2 - Cumulative
F25: Delay (years) | S25: Delay (years)
A26: Policy year | B26: 0 | C26: 1 | D26: 2 | E26: 3 | F26: 4 | G26: 5 | H26: 6 | I26: 7 | J26: 8 | K26: 9 | L26: Ultimate | N26: Policy year | O26: 0 | P26: 1 | Q26: 2 | R26: 3 | S26: 4 | T26: 5 | U26: 6 | V26: 7 | W26: 8 | X26: 9
A27: =A11 -> 2005 | B27: =B11 -> 50 | C27: =IF($A27+C$26>Latest_Year,"",C11+B27) -> 76 | D27: =IF($A27+D$26>Latest_Year,"",D11+C27) -> 81 | E27: =IF($A27+E$26>Latest_Year,"",E11+D27) -> 84 | F27: =IF($A27+F$26>Latest_Year,"",F11+E27) -> 86 | G27: =IF($A27+G$26>Latest_Year,"",G11+F27) -> 86 | H27: =IF($A27+H$26>Latest_Year,"",H11+G27) -> 86 | I27: =IF($A27+I$26>Latest_Year,"",I11+H27) -> 86 | J27: =IF($A27+J$26>Latest_Year,"",J11+I27) -> 86 | K27: =IF($A27+K$26>Latest_Year,"",K11+J27) -> 86 | N27: =A27 -> 2005 | O27: =B11 -> 50 | P27: =IF($A27+P$26>Latest_Year-1,"",C11+O27) -> 76 | Q27: =IF($A27+Q$26>Latest_Year-1,"",D11+P27) -> 81 | R27: =IF($A27+R$26>Latest_Year-1,"",E11+Q27) -> 84 | S27: =IF($A27+S$26>Latest_Year-1,"",F11+R27) -> 86 | T27: =IF($A27+T$26>Latest_Year-1,"",G11+S27) -> 86 | U27: =IF($A27+U$26>Latest_Year-1,"",H11+T27) -> 86 | V27: =IF($A27+V$26>Latest_Year-1,"",I11+U27) -> 86 | W27: =IF($A27+W$26>Latest_Year-1,"",J11+V27) -> 86
A28: =A12 -> 2006 | B28: =B12 -> 41 | C28: =IF($A28+C$26>Latest_Year,"",C12+B28) -> 69 | D28: =IF($A28+D$26>Latest_Year,"",D12+C28) -> 82 | E28: =IF($A28+E$26>Latest_Year,"",E12+D28) -> 88 | F28: =IF($A28+F$26>Latest_Year,"",F12+E28) -> 92 | G28: =IF($A28+G$26>Latest_Year,"",G12+F28) -> 92 | H28: =IF($A28+H$26>Latest_Year,"",H12+G28) -> 92 | I28: =IF($A28+I$26>Latest_Year,"",I12+H28) -> 92 | J28: =IF($A28+J$26>Latest_Year,"",J12+I28) -> 92 | K28: =IF($A28+K$26>Latest_Year,"",K12+J28) | N28: =A28 -> 2006 | O28: =B12 -> 41 | P28: =IF($A28+P$26>Latest_Year-1,"",C12+O28) -> 69 | Q28: =IF($A28+Q$26>Latest_Year-1,"",D12+P28) -> 82 | R28: =IF($A28+R$26>Latest_Year-1,"",E12+Q28) -> 88 | S28: =IF($A28+S$26>Latest_Year-1,"",F12+R28) -> 92 | T28: =IF($A28+T$26>Latest_Year-1,"",G12+S28) -> 92 | U28: =IF($A28+U$26>Latest_Year-1,"",H12+T28) -> 92 | V28: =IF($A28+V$26>Latest_Year-1,"",I12+U28) -> 92 | W28: =IF($A28+W$26>Latest_Year-1,"",J12+V28)
A29: =A13 -> 2007 | B29: =B13 -> 65 | C29: =IF($A29+C$26>Latest_Year,"",C13+B29) -> 98 | D29: =IF($A29+D$26>Latest_Year,"",D13+C29) -> 108 | E29: =IF($A29+E$26>Latest_Year,"",E13+D29) -> 110 | F29: =IF($A29+F$26>Latest_Year,"",F13+E29) -> 110 | G29: =IF($A29+G$26>Latest_Year,"",G13+F29) -> 110 | H29: =IF($A29+H$26>Latest_Year,"",H13+G29) -> 110 | I29: =IF($A29+I$26>Latest_Year,"",I13+H29) -> 110 | J29: =IF($A29+J$26>Latest_Year,"",J13+I29) | K29: =IF($A29+K$26>Latest_Year,"",K13+J29) | N29: =A29 -> 2007 | O29: =B13 -> 65 | P29: =IF($A29+P$26>Latest_Year-1,"",C13+O29) -> 98 | Q29: =IF($A29+Q$26>Latest_Year-1,"",D13+P29) -> 108 | R29: =IF($A29+R$26>Latest_Year-1,"",E13+Q29) -> 110 | S29: =IF($A29+S$26>Latest_Year-1,"",F13+R29) -> 110 | T29: =IF($A29+T$26>Latest_Year-1,"",G13+S29) -> 110 | U29: =IF($A29+U$26>Latest_Year-1,"",H13+T29) -> 110 | V29: =IF($A29+V$26>Latest_Year-1,"",I13+U29) | W29: =IF($A29+W$26>Latest_Year-1,"",J13+V29)
A30: =A14 -> 2008 | B30: =B14 -> 83 | C30: =IF($A30+C$26>Latest_Year,"",C14+B30) -> 130 | D30: =IF($A30+D$26>Latest_Year,"",D14+C30) -> 138 | E30: =IF($A30+E$26>Latest_Year,"",E14+D30) -> 144 | F30: =IF($A30+F$26>Latest_Year,"",F14+E30) -> 145 | G30: =IF($A30+G$26>Latest_Year,"",G14+F30) -> 145 | H30: =IF($A30+H$26>Latest_Year,"",H14+G30) -> 146 | I30: =IF($A30+I$26>Latest_Year,"",I14+H30) | J30: =IF($A30+J$26>Latest_Year,"",J14+I30) | K30: =IF($A30+K$26>Latest_Year,"",K14+J30) | N30: =A30 -> 2008 | O30: =B14 -> 83 | P30: =IF($A30+P$26>Latest_Year-1,"",C14+O30) -> 130 | Q30: =IF($A30+Q$26>Latest_Year-1,"",D14+P30) -> 138 | R30: =IF($A30+R$26>Latest_Year-1,"",E14+Q30) -> 144 | S30: =IF($A30+S$26>Latest_Year-1,"",F14+R30) -> 145 | T30: =IF($A30+T$26>Latest_Year-1,"",G14+S30) -> 145 | U30: =IF($A30+U$26>Latest_Year-1,"",H14+T30) | V30: =IF($A30+V$26>Latest_Year-1,"",I14+U30) | W30: =IF($A30+W$26>Latest_Year-1,"",J14+V30)
A31: =A15 -> 2009 | B31: =B15 -> 120 | C31: =IF($A31+C$26>Latest_Year,"",C15+B31) -> 165 | D31: =IF($A31+D$26>Latest_Year,"",D15+C31) -> 181 | E31: =IF($A31+E$26>Latest_Year,"",E15+D31) -> 190 | F31: =IF($A31+F$26>Latest_Year,"",F15+E31) -> 192 | G31: =IF($A31+G$26>Latest_Year,"",G15+F31) -> 194 | H31: =IF($A31+H$26>Latest_Year,"",H15+G31) | I31: =IF($A31+I$26>Latest_Year,"",I15+H31) | J31: =IF($A31+J$26>Latest_Year,"",J15+I31) | K31: =IF($A31+K$26>Latest_Year,"",K15+J31) | N31: =A31 -> 2009 | O31: =B15 -> 120 | P31: =IF($A31+P$26>Latest_Year-1,"",C15+O31) -> 165 | Q31: =IF($A31+Q$26>Latest_Year-1,"",D15+P31) -> 181 | R31: =IF($A31+R$26>Latest_Year-1,"",E15+Q31) -> 190 | S31: =IF($A31+S$26>Latest_Year-1,"",F15+R31) -> 192 | T31: =IF($A31+T$26>Latest_Year-1,"",G15+S31) | U31: =IF($A31+U$26>Latest_Year-1,"",H15+T31) | V31: =IF($A31+V$26>Latest_Year-1,"",I15+U31) | W31: =IF($A31+W$26>Latest_Year-1,"",J15+V31)
