Workbook
Name _b2: #REF!
Name a: #REF!
Name a: #REF!
Name AccountList2007: #REF!
Name AccountList2007: #REF!
Name AccountList2008: #REF!
Name Agg_Marman_Claims: #REF!
Name Agg_Marman_Summary: #REF!
Name Aggregate_Summary: #REF!
Name Avg_Delay: '[1]Frequency analysis'!$X$14
Name Avg_Delay: #REF!
Name avg_obs_delay: #REF!
Name Binder_Table: [2]Console!$B$156:$C$172
Name binder_table_mid: [2]Console!$B$156:$G$172
Name biz_type_table: [2]Console!$B$70:$C$71
Name biz_type_table_mid: [2]Console!$B$70:$G$71
Name Chart_Points: '[3]Standard severity models'!$U$14
Name Claims_Inflation: '[4]2. Claims data'!$D$6
Name cli_output2: #REF!
Name cli_output2: #REF!
Name COB_BT_Combo_Table: [2]Console!$B$176:$C$194
Name COB_BT_Combo_Table_mid: [2]Console!$B$176:$G$194
Name COB_table: [2]Console!$B$75:$C$86
Name COB_table_mid: [2]Console!$B$75:$G$86
Name Company: #REF!
Name Company: #REF!
Name Contract_Basis: [5]Assumptions!$L$7
Name Contract_length_table: [2]Console!$B$90:$C$93
Name Contract_length_table_mid: [2]Console!$B$90:$G$93
Name Corr_Factor: [5]Assumptions!$L$13
Name country_table: [2]Console!$K$74:$L$182
Name country_table_mid: [2]Console!$K$74:$P$182
Name csi: [6]Assumptions!$C$28
Name csi_client: #REF!
Name csi_client: #REF!
Name csi_market: #REF!
Name csi_mkt: [6]Aggregation!#REF!
Name csi_old: #REF!
Name csi_old: #REF!
Name csi_orig: [6]Aggregation!$D$35
Name csi_std_client: #REF!
Name csi_std_client: #REF!
Name CurrentYear: #REF!
Name Data_Set: '[7]1. IBNR Calculations'!$W$7
Name database1: '[8]2007 vs 2008 (2)'!$A$8:$T$130
Name database1: '[9]2007 vs 2008 (2)'!$A$8:$T$130
Name Database2: '[8]2007 vs 2008'!$A$8:$T$130
Name Dcsi_mkt: [6]Aggregation!#REF!
Name Dcsi_mkt: [6]Aggregation!#REF!
Name Default_Inflation: [5]Assumptions!$L$9
Name disct_rate_cli: #REF!
Name disct_rate_cli: #REF!
Name disct_rate_mkt: #REF!
Name dlambda_client: #REF!
Name Dlambda_het: [6]Aggregation!#REF!
Name dlambda_market: #REF!
Name dlambda_market: #REF!
Name Dlambda_mkt: [6]Aggregation!#REF!
Name Dlambda_mkt: [6]Aggregation!#REF!
Name Dlambda_mkt_2m: [6]Aggregation!#REF!

Sheet 00. DISCLAIMER
B4: This data is intended for purely educational purposes and as supporting material for the textbook "Pricing in General Insurance" by Pietro Parodi and comes with no guarantee. It should not be relied upon for use in a professional context. Also note that the data included here is realistic but not real.

Sheet Policy data
A1: Policy ID | B1: Inception Date | C1: Expiry Date | D1: Territory | E1: Client | F1: Class of Business | G1: Insured's Industry Sector | H1: Currency | I1: Limit Amount | J1: Excess / Deductible Amount | K1: Layer Type | L1: Gross Premium | M1: Brokerage Deductions | N1: Net Premium
A2: Policy_7022 | B2: 39448 | C2: 39814 | D2: Spain | E2: Client_2 | F2: PI | G2: Project management | H2: EUR | I2: 3000000 | J2: 30000 | K2: Stand Alone | L2: 7056.338 | M2: 1587.6761 | N2: 5468.662
A3: Policy_16141 | B3: 39656 | C3: 40205 | D3: Australia | E3: Client_7 | F3: D&O | G3: Manufacturing | H3: AUD | I3: 10000000 | J3: 10000000 | K3: Excess | L3: 16978.743 | M3: 3395.7415 | N3: 13583.001
A4: Policy_20434 | B4: 39658 | C4: 42213 | D4: United Kingdom | E4: Client_15 | F4: D&O | G4: Energy | H4: GBP | I4: 20000000 | J4: 25000 | K4: Stand Alone | L4: 260937.5 | M4: 52187.517 | N4: 208749.98
A5: Policy_7870 | B5: 39814 | C5: 40179 | D5: Russian Federation | E5: Client_17 | F5: D&O | G5: Technology, Media, Telecomunications | H5: USD | I5: 15000000 | J5: 15000000 | K5: Excess | L5: 75000 | M5: 16875 | N5: 58125
A6: Policy_19714 | B6: 39814 | C6: 40179 | D6: United States | E6: Client_23 | F6: PI | G6: Legal Services - Solicitor | H6: USD | I6: 20000000 | J6: 3000000 | K6: Primary | L6: 1719000 | M6: 249255 | N6: 1469745
A7: Policy_20703 | B7: 39399 | C7: 39765 | D7: Ecuador | E7: Client_25 | F7: D&O | G7: Administration Services | H7: USD | I7: 1000000 | J7: Nil | K7: Stand Alone | L7: 7524 | M7: 1504.8 | N7: 6019.2
A8: Policy_3561 | B8: 39814 | C8: 40179 | D8: Russian Federation | E8: Client_29 | F8: D&O | G8: Property | H8: USD | I8: 10000000 | J8: 15000000 | K8: Excess | L8: 95000 | M8: 21375 | N8: 73625
A9: Policy_19411 | B9: 39405 | C9: 39801 | D9: Trinidad and Tobago | E9: Client_30 | F9: D&O | G9: Manufacturing | H9: USD | I9: 2500000 | J9: Nil | K9: Stand Alone | L9: 4869.86 | M9: 973.97 | N9: 3895.89
A10: Policy_20202 | B10: 39814 | C10: 40179 | D10: United States | E10: Client_33 | F10: PI | G10: Legal Services - Solicitor | H10: USD | I10: 30000000 | J10: 20000000 | K10: Excess | L10: 975000 | M10: 142350 | N10: 832650
A11: Policy_16861 | B11: 39417 | C11: 39782 | D11: Turks And Caicos Islands | E11: Client_35 | F11: D&O | G11: Entertainment, Leisure and Hospitality | H11: USD | I11: 2000000 | J11: Nil | K11: Stand Alone | L11: 8500 | M11: 1700 | N11: 6800
A12: Policy_8197 | B12: 39814 | C12: 40179 | D12: United States | E12: Client_37 | F12: PI | G12: Legal Services - Solicitor | H12: USD | I12: 20000000 | J12: 1000000 | K12: Primary | L12: 366366.79 | M12: 54955.03 | N12: 311411.76
A13: Policy_1868 | B13: 39417 | C13: 39782 | D13: Turks And Caicos Islands | E13: Client_38 | F13: D&O | G13: Entertainment, Leisure and Hospitality | H13: USD | I13: 4000000 | J13: Nil | K13: Stand Alone | L13: 8500 | M13: 1700 | N13: 6800
A14: Policy_17432 | B14: 39814 | C14: 40179 | D14: Russian Federation | E14: Client_42 | F14: D&O | G14: Technology, Media, Telecomunications | H14: USD | I14: 15000000 | J14: 15000000 | K14: Excess | L14: 80000 | M14: 18000 | N14: 62000
A15: Policy_5043 | B15: 39814 | C15: 40179 | D15: United States | E15: Client_44 | F15: PI | G15: Legal Services - Solicitor | H15: USD | I15: 20000000 | J15: 20000000 | K15: Excess | L15: 158564.39 | M15: 23784.66 | N15: 134779.73
A16: Policy_6034 | B16: 39814 | C16: 40179 | D16: France | E16: Client_45 | F16: D&O | G16: Retail, Distribution and Wholesale | H16: USD | I16: 15000000 | J16: 50000 | K16: Primary | L16: 20700 | M16: 0 | N16: 20700
A17: Policy_15606 | B17: 39417 | C17: 39783 | D17: Peru | E17: Client_52 | F17: D&O | G17: Entertainment, Leisure and Hospitality | H17: USD | I17: 15000000 | J17: Nil | K17: Stand Alone | L17: 27500 | M17: 5500 | N17: 22000
A18: Policy_20495 | B18: 39814 | C18: 40179 | D18: United States | E18: Client_56 | F18: PI | G18: Legal Services - Solicitor | H18: USD | I18: 30000000 | J18: 40000000 | K18: Excess | L18: 100191.78 | M18: 12523.98 | N18: 87667.8
A19: Policy_12528 | B19: 39417 | C19: 39783 | D19: Brazil | E19: Client_57 | F19: D&O | G19: Mining | H19: USD | I19: 25000000 | J19: 1500000 | K19: Primary | L19: 458289.35 | M19: 0 | N19: 458289.35
A20: Policy_5717 | B20: 40148 | C20: 40513 | D20: Austria | E20: Client_59 | F20: D&O | G20: Mining | H20: USD | I20: 25000000 | J20: 1500000 | K20: Primary | L20: 653797.48 | M20: 68452.62 | N20: 585344.86
A21: Policy_5663 | B21: 39814 | C21: 40179 | D21: France | E21: Client_61 | F21: D&O | G21: Retail, Distribution and Wholesale | H21: USD | I21: 5000000 | J21: 25000000 | K21: Excess | L21: 22500 | M21: 0 | N21: 22500
A22: Policy_12253 | B22: 39814 | C22: 40179 | D22: United States | E22: Client_63 | F22: PI | G22: Legal Services - Solicitor | H22: USD | I22: 25000000 | J22: 50000000 | K22: Excess | L22: 195000 | M22: 34125 | N22: 160875
A23: Policy_14066 | B23: 39814 | C23: 40179 | D23: Russian Federation | E23: Client_65 | F23: D&O | G23: Technology, Media, Telecomunications | H23: USD | I23: 60000000 | J23: 160000000 | K23: Excess | L23: 230000 | M23: 51750 | N23: 178250
A24: Policy_13105 | B24: 39814 | C24: 40179 | D24: United Kingdom | E24: Client_67 | F24: D&O | G24: Manufacturing | H24: EUR | I24: 7500000 | J24: Nil | K24: Stand Alone | L24: 48512.324 | M24: 1212.8081 | N24: 47299.516
A25: Policy_6331 | B25: 40179 | C25: 40544 | D25: France | E25: Client_68 | F25: D&O | G25: Manufacturing | H25: EUR | I25: 7500000 | J25: Nil | K25: Stand Alone | L25: 79971.831 | M25: 0 | N25: 79971.831
A26: Policy_14570 | B26: 39617 | C26: 39982 | D26: Channel Islands | E26: Client_69 | F26: D&O | G26: Consultancy | H26: GBP | I26: 5000000 | J26: Nil | K26: Primary | L26: 14028 | M26: 2805.6 | N26: 11222.4
A27: Policy_20560 | B27: 39814 | C27: 40179 | D27: Russian Federation | E27: Client_70 | F27: D&O | G27: Technology, Media, Telecomunications | H27: USD | I27: 50000000 | J27: 220000000 | K27: Excess | L27: 98000 | M27: 22050 | N27: 75950
A28: Policy_18502 | B28: 39414 | C28: 39629 | D28: El Salvador | E28: Client_72 | F28: D&O | G28: Retail, Distribution and Wholesale | H28: USD | I28: 5000000 | J28: Nil | K28: Stand Alone | L28: 14863 | M28: 2229.45 | N28: 12633.55
A29: Policy_13965 | B29: 39814 | C29: 40179 | D29: Russian Federation | E29: Client_78 | F29: D&O | G29: Technology, Media, Telecomunications | H29: USD | I29: 15000000 | J29: 15000000 | K29: Excess | L29: 110000 | M29: 24750 | N29: 85250
A30: Policy_11794 | B30: 39822 | C30: 40186 | D30: United Kingdom | E30: Client_87 | F30: PI | G30: Surveyor | H30: GBP | I30: 5000000 | J30: 100000 | K30: Primary | L30: 83500 | M30: 0 | N30: 83500
A31: Policy_877 | B31: 39447 | C31: 39813 | D31: Spain | E31: Client_91 | F31: PI | G31: Engineering | H31: EUR | I31: 15000000 | J31: 15000000 | K31: Excess | L31: 346936.62 | M31: 69387.324 | N31: 277549.3
A32: Policy_9873 | B32: 39822 | C32: 40186 | D32: United Kingdom | E32: Client_92 | F32: PI | G32: Surveyor | H32: GBP | I32: 10000000 | J32: 5000000 | K32: Excess | L32: 40706.25 | M32: 0 | N32: 40706.25
A33: Policy_7533 | B33: 39447 | C33: 39813 | D33: Spain | E33: Client_94 | F33: PI | G33: Engineering | H33: EUR | I33: 10000000 | J33: 10000000 | K33: Excess | L33: 393978.87 | M33: 78795.775 | N33: 315183.1
A34: Policy_15802 | B34: 39822 | C34: 40186 | D34: United Kingdom | E34: Client_98 | F34: PI | G34: Surveyor | H34: GBP | I34: 5000000 | J34: 10000000 | K34: Excess | L34: 10771.5 | M34: 0 | N34: 10771.5
A35: Policy_17631 | B35: 39821 | C35: 40186 | D35: United States | E35: Client_99 | F35: PI | G35: Health & Safety | H35: USD | I35: 5000000 | J35: 100000 | K35: Stand Alone | L35: 145000 | M35: 25375 | N35: 119625
A36: Policy_9321 | B36: 39439 | C36: 39805 | D36: Trinidad and Tobago | E36: Client_104 | F36: D&O | G36: Manufacturing | H36: USD | I36: 2000000 | J36: Nil | K36: Stand Alone | L36: 5500 | M36: 1100 | N36: 4400
A37: Policy_5510 | B37: 39823 | C37: 40237 | D37: Cyprus | E37: Client_108 | F37: D&O | G37: Utilities - water, gas, electricity | H37: USD | I37: 20000000 | J37: Nil | K37: Stand Alone | L37: 61249.31 | M37: 13781.1 | N37: 47468.21
A38: Policy_2928 | B38: 39428 | C38: 39794 | D38: Turks And Caicos Islands | E38: Client_110 | F38: PI | G38: Administration Services | H38: USD | I38: 5000000 | J38: 150000 | K38: Stand Alone | L38: 65669 | M38: 13133.8 | N38: 52535.2
A39: Policy_5945 | B39: 39828 | C39: 40192 | D39: United Kingdom | E39: Client_113 | F39: D&O | G39: Engineering | H39: USD | I39: 10000000 | J39: Nil | K39: Stand Alone | L39: 70300 | M39: 14060 | N39: 56240
A40: Policy_7136 | B40: 39445 | C40: 39811 | D40: Trinidad and Tobago | E40: Client_117 | F40: D&O | G40: Entertainment, Leisure and Hospitality | H40: USD | I40: 1582278 | J40: Nil | K40: Stand Alone | L40: 3461.74 | M40: 692.35 | N40: 2769.39
...

Sheet Claims data (Reinsurance - GL)
B3: Claim ID | C3: Loss date | D3: Loss Year | E3: Policy year | F3: Type | G3: 2004 | H3: 2005 | I3: 2006 | J3: 2007 | K3: 2008 | L3: 2009 | M3: 2010 | N3: 2011
B4: 210245 | C4: 38171 | D4: 2004 | F4: Paid | G4: 0 | H4: 0 | I4: 300300.42 | J4: 300300.42 | K4: 300300.42 | L4: 720261.26 | M4: 720261.26 | N4: 720261.26
B5: 210245 | C5: 38171 | D5: 2004 | F5: O/S | G5: 4050000 | H5: 2500000 | I5: 469699.58 | J5: 413577.92 | K5: 419960.84 | L5: 0 | M5: 0 | N5: 0
B6: 210245 | C6: 38171 | D6: 2004 | F6: Incurred | G6: 4050000 | H6: 2500000 | I6: 770000 | J6: 713878.34 | K6: 720261.26 | L6: 720261.26 | M6: 720261.26 | N6: 720261.26
B7: 211136 | C7: 38172 | D7: 2004 | F7: Paid | G7: 0 | H7: 0 | I7: 0 | J7: 0 | K7: 0 | L7: 0 | M7: 0 | N7: 0
B8: 211136 | C8: 38172 | D8: 2004 | F8: O/S | G8: 190000 | H8: 140000 | I8: 140000 | J8: 0 | K8: 0 | L8: 0 | M8: 0 | N8: 0
B9: 211136 | C9: 38172 | D9: 2004 | F9: Incurred | G9: 190000 | H9: 140000 | I9: 140000 | J9: 0 | K9: 0 | L9: 0 | M9: 0 | N9: 0
B10: 211219 | C10: 38171 | D10: 2004 | F10: Paid | G10: 0 | H10: 0 | I10: 0 | J10: 0 | K10: 0 | L10: 0 | M10: 0 | N10: 0
B11: 211219 | C11: 38171 | D11: 2004 | F11: O/S | G11: 0 | H11: 0 | I11: 0 | J11: 0 | K11: 0 | L11: 0 | M11: 0 | N11: 0
B12: 211219 | C12: 38171 | D12: 2004 | F12: Incurred | G12: 0 | H12: 0 | I12: 0 | J12: 0 | K12: 0 | L12: 0 | M12: 0 | N12: 0
B13: 213033 | C13: 38169 | D13: 2004 | F13: Paid | G13: 0 | H13: 0 | I13: 0 | J13: 0 | K13: 0 | L13: 0 | M13: 0 | N13: 0
B14: 213033 | C14: 38169 | D14: 2004 | F14: O/S | G14: 0 | H14: 0 | I14: 0 | J14: 0 | K14: 0 | L14: 0 | M14: 0 | N14: 0
B15: 213033 | C15: 38169 | D15: 2004 | F15: Incurred | G15: 0 | H15: 0 | I15: 0 | J15: 0 | K15: 0 | L15: 0 | M15: 0 | N15: 0
... B66: 240234 | C66: 38214 | D66: 2004 | F66: Incurred | G66: 0 | H66: 0 | I66: 0 | J66: 0 | K66: 0 | L66: 0 | M66: 0 | N66: 0
B67: 244962 | C67: 38219 | D67: 2004 | F67: Paid | H67: 0 | I67: 0 | J67: 0 | K67: 0 | L67: 58809.13 | M67: 58809.13 | N67: 58809.13
B68: 244962 | C68: 38219 | D68: 2004 | F68: O/S | H68: 10000 | I68: 10000 | J68: 0 | K68: 60000 | L68: 0 | M68: 0 | N68: 0
B69: 244962 | C69: 38219 | D69: 2004 | F69: Incurred | G69: =SUM(G67:G68) -> 0 | H69: =SUM(H67:H68) -> 10000 | I69: =SUM(I67:I68) -> 10000 | J69: =SUM(J67:J68) -> 0 | K69: =SUM(K67:K68) -> 60000 | L69: =SUM(L67:L68) -> 58809.13 | M69: =SUM(M67:M68) -> 58809.13 | N69: =SUM(N67:N68) -> 58809.13
B70: 251322 | C70: 38207 | D70: 2004 | F70: Paid | G70: 2027.63 | H70: 2027.63 | I70: 2027.63 | J70: 2027.63 | K70: 2027.63 | L70: 2027.63 | M70: 2027.63 | N70: 2027.63
B71: 251322 | C71: 38207 | D71: 2004 | F71: O/S | G71: 0 | H71: 0 | I71: 0 | J71: 0 | K71: 0 | L71: 0 | M71: 0 | N71: 0
B72: 251322 | C72: 38207 | D72: 2004 | F72: Incurred | G72: =SUM(G70:G71) -> 2027.63 | H72: =SUM(H70:H71) -> 2027.63 | I72: =SUM(I70:I71) -> 2027.63 | J72: =SUM(J70:J71) -> 2027.63 | K72: =SUM(K70:K71) -> 2027.63 | L72: =SUM(L70:L71) -> 2027.63 | M72: =SUM(M70:M71) -> 2027.63 | N72: =SUM(N70:N71) -> 2027.63
B73: 251355 | C73: 38178 | D73: 2004 | F73: Paid | G73: 2585.81 | H73: 2585.81 | I73: 2585.81 | J73: 2585.81 | K73: 2585.81 | L73: 2585.81 | M73: 2585.81 | N73: 2585.81
B74: 251355 | C74: 38178 | D74: 2004 | F74: O/S | G74: 0 | H74: 0 | I74: 0 | J74: 0 | K74: 0 | L74: 0 | M74: 0 | N74: 0
B75: 251355 | C75: 38178 | D75: 2004 | F75: Incurred | G75: =SUM(G73:G74) -> 2585.81 | H75: =SUM(H73:H74) -> 2585.81 | I75: =SUM(I73:I74) -> 2585.81 | J75: =SUM(J73:J74) -> 2585.81 | K75: =SUM(K73:K74) -> 2585.81 | L75: =SUM(L73:L74) -> 2585.81 | M75: =SUM(M73:M74) -> 2585.81 | N75: =SUM(N73:N74) -> 2585.81
B76: 253344 | C76: 38225 | D76: 2004 | F76: Paid | G76: 0 | H76: 0 | I76: 0 | J76: 0 | K76: 130000 | L76: 130000 | M76: 396094 | N76: 396094
B77: 253344 | C77: 38225 | D77: 2004 | F77: O/S | G77: 1375000 | H77: 1475000 | I77: 1475000 | J77: 1475000 | K77: 1345000 | L77: 1345000 | M77: 0.01 | N77: 0.01
B78: 253344 | C78: 38225 | D78: 2004 | F78: Incurred | G78: =SUM(G76:G77) -> 1375000 | H78: =SUM(H76:H77) -> 1475000 | I78: =SUM(I76:I77) -> 1475000 | J78: =SUM(J76:J77) -> 1475000 | K78: =SUM(K76:K77) -> 1475000 | L78: =SUM(L76:L77) -> 1475000 | M78: =SUM(M76:M77) -> 396094.01 | N78: =SUM(N76:N77) -> 396094.01
B79: 254201 | C79: 38224 | D79: 2004 | F79: Paid | G79: 0 | H79: 0 | I79: 0 | J79: 0 | K79: 0 | L79: 0 | M79: 0 | N79: 0
B80: 254201 | C80: 38224 | D80: 2004 | F80: O/S | G80: 0 | H80: 0 | I80: 0 | J80: 0 | K80: 0 | L80: 0 | M80: 0 | N80: 0
B81: 254201 | C81: 38224 | D81: 2004 | F81: Incurred | G81: =SUM(G79:G80) -> 0 | H81: =SUM(H79:H80) -> 0 | I81: =SUM(I79:I80) -> 0 | J81: =SUM(J79:J80) -> 0 | K81: =SUM(K79:K80) -> 0 | L81: =SUM(L79:L80) -> 0 | M81: =SUM(M79:M80) -> 0 | N81: =SUM(N79:N80) -> 0
B82: 254474 | C82: 38212 | D82: 2004 | F82: Paid | G82: 0 | H82: 0 | I82: 0 | J82: 0 | K82: 0 | L82: 0 | M82: 0 | N82: 0
B83: 254474 | C83: 38212 | D83: 2004 | F83: O/S | G83: 55000 | H83: 60000 | I83: 60000 | J83: 0 | K83: 0 | L83: 0 | M83: 0 | N83: 0
B84: 254474 | C84: 38212 | D84: 2004 | F84: Incurred | G84: =SUM(G82:G83) -> 55000 | H84: =SUM(H82:H83) -> 60000 | I84: =SUM(I82:I83) -> 60000 | J84: =SUM(J82:J83) -> 0 | K84: =SUM(K82:K83) -> 0 | L84: =SUM(L82:L83) -> 0 | M84: =SUM(M82:M83) -> 0 | N84: =SUM(N82:N83) -> 0
B85: 254581 | C85: 38201 | D85: 2004 | F85: Paid | G85: 2584.53 | H85: 2584.53 | I85: 2584.53 | J85: 2584.53 | K85: 2584.53 | L85: 2584.53 | M85: 2584.53 | N85: 2584.53
B86: 254581 | C86: 38201 | D86: 2004 | F86: O/S | G86: 0.23 | H86: 0.23 | I86: 0.23 | J86: 0.23 | K86: 0.23 | L86: 0.23 | M86: 0.23 | N86: 0.23
B87: 254581 | C87: 38201 | D87: 2004 | F87: Incurred | G87: =SUM(G85:G86) -> 2584.76 | H87: =SUM(H85:H86) -> 2584.76 | I87: =SUM(I85:I86) -> 2584.76 | J87: =SUM(J85:J86) -> 2584.76 | K87: =SUM(K85:K86) -> 2584.76 | L87: =SUM(L85:L86) -> 2584.76 | M87: =SUM(M85:M86) -> 2584.76 | N87: =SUM(N85:N86) -> 2584.76
B88: 257410 | C88: 38231 | D88: 2004 | F88: Paid | G88: 0 | H88: 0 | I88: 0 | J88: 0 | K88: 0 | L88: 0 | M88: 0 | N88: 0
B89: 257410 | C89: 38231 | D89: 2004 | F89: O/S | G89: 0 | H89: 0 | I89: 0 | J89: 0 | K89: 0 | L89: 0 | M89: 0 | N89: 0
B90: 257410 | C90: 38231 | D90: 2004 | F90: Incurred | G90: 569.23 | H90: 2929.38 | I90: 2929.38 | J90: 2929.38 | K90: 2929.38 | L90: 2929.38 | M90: 2929.38 | N90: 2929.38
B91: 259119 | C91: 38228 | D91: 2004 | F91: Paid | G91: 0 | H91: 0 | I91: 8578.45 | J91: 8578.45 | K91: 8578.45 | L91: 8578.45 | M91: 8578.45 | N91: 8578.45
B92: 259119 | C92: 38228 | D92: 2004 | F92: O/S | G92: 425000 | H92: 425000 | I92: 0 | J92: 0 | K92: 0 | L92: 0 | M92: 0 | N92: 0
...

Sheet Claims data (PL)
D2: ASSUMPTIONS
C3: Data as-at date | D3: 41973
C4: Policy inception month | D4: 4
C5: Revalue at | D5: 42278
C6: Claims inflation | D6: 0.05
C7: Destination currency | D7: GBP
C8: Exchange rate | D8: 1
C9: EEL (£) | D9: 100000
C10: Limit (£) | D10: 5000000 | Q10: =SUM(Q13:Q1730) -> 22537551
C11: AAD (£) | D11: 2500000 | AC11: =SUM(AC13:AC1730) -> 0 | AD11: =SUM(AD13:AD1730) -> 0
A12: Claim ID | B12: Claimant Name | C12: Class of Business | D12: Loss date | E12: Reporting date | F12: Policy Year | G12: Claim description | H12: Currency | I12: Paid | J12: Outstanding | K12: Total incurred | L12: Fees | M12: Recoveries | N12: Overall amount | O12: Non-zero? (1=Yes) | P12: Overall (destination currency) | Q12: Overall amount (revalued) | R12: Retained | S12: Ceded | T12: Delay (days) | U12: Claim Status | V12: Exposure
A13: Claim_1 | B13: Name_1 | C13: Public Liability Bodily Injury | D13: 40195 | E13: 40561 | F13: =IF(MONTH(D13)<$D$4,YEAR(D13)-1,YEAR(D13)) -> 2009 | G13: Contact With | H13: GBP | I13: 17056.23 | J13: 0 | K13: 17056.23 | L13: 0 | M13: 0 | N13: 17056.23 | O13: =IF(N13=0,0,1) -> 1 | P13: =N13*$D$8 -> 17056.23 | Q13: =P13*(1+$D$6)^(($D$5-D13)/365.25) -> 22528.092 | R13: =MIN($D$9,Q13)+MAX(Q13-$D$9-$D$10,0) -> 22528.092 | S13: =MIN(MAX(Q13-$D$9,0),$D$10) -> 0 | T13: =E13-D13 -> 366 | U13: Closed | V13: =VLOOKUP(F13,'Exposure data (PL)'!$J$3:$L$14,3,FALSE) -> 855.15321
A14: Claim_2 | B14: Name_2 | C14: Public Liability Bodily Injury | D14: 39144 | E14: 39195 | F14: =IF(MONTH(D14)<$D$4,YEAR(D14)-1,YEAR(D14)) -> 2006 | G14: Slip,Trip Or Fall-Same Level | H14: GBP | I14: 27297.096 | J14: 0 | K14: 27297.096 | L14: 0 | M14: 0 | N14: 27297.096 | O14: =IF(N14=0,0,1) -> 1 | P14: =N14*$D$8 -> 27297.096 | Q14: =P14*(1+$D$6)^(($D$5-D14)/365.25) -> 41488.68 | R14: =MIN($D$9,Q14)+MAX(Q14-$D$9-$D$10,0) -> 41488.68 | S14: =MIN(MAX(Q14-$D$9,0),$D$10) -> 0 | T14: =E14-D14 -> 51 | U14: Closed | V14: =VLOOKUP(F14,'Exposure data (PL)'!$J$3:$L$14,3,FALSE) -> 543.66953
A15: Claim_3 | B15: Name_3 | C15: Public Liability Bodily Injury | D15: 39268 | E15: 39622 | F15: =IF(MONTH(D15)<$D$4,YEAR(D15)-1,YEAR(D15)) -> 2007 | G15: Slip,Trip Or Fall-Elevated Surfaces | H15: GBP | I15: 2230.5459 | J15: 0 | K15: 2230.5459 | L15: 0 | M15: 0 | N15: 2230.5459 | O15: =IF(N15=0,0,1) -> 1 | P15: =N15*$D$8 -> 2230.5459 | Q15: =P15*(1+$D$6)^(($D$5-D15)/365.25) -> 3334.5 | R15: =MIN($D$9,Q15)+MAX(Q15-$D$9-$D$10,0) -> 3334.5 | S15: =MIN(MAX(Q15-$D$9,0),$D$10) -> 0 | T15: =E15-D15 -> 354 | U15: Closed | V15: =VLOOKUP(F15,'Exposure data (PL)'!$J$3:$L$14,3,FALSE) -> 616.17084
A16: Claim_4 | B16: Name_4 | C16: Public Liability Bodily Injury | D16: 39605 | E16: 40201 | F16: =IF(MONTH(D16)<$D$4,YEAR(D16)-1,YEAR(D16)) -> 2008 | G16: Slip,Trip Or Fall-Same Level | H16: GBP | I16: 13516.419 | J16: 0 | K16: 13516.419 | L16: 0 | M16: 1189.4449 | N16: 12326.974 | O16: =IF(N16=0,0,1) -> 1 | P16: =N16*$D$8 -> 12326.974 | Q16: =P16*(1+$D$6)^(($D$5-D16)/365.25) -> 17616.743 | R16: =MIN($D$9,Q16)+MAX(Q16-$D$9-$D$10,0) -> 17616.743 | S16: =MIN(MAX(Q16-$D$9,0),$D$10) -> 0 | T16: =E16-D16 -> 596 | U16: Closed | V16: =VLOOKUP(F16,'Exposure data (PL)'!$J$3:$L$14,3,FALSE) -> 677.15217
A17: Claim_5 | B17: Name_5 | C17: Public Liability Bodily Injury | D17: 40344 | E17: 40348 | F17: =IF(MONTH(D17)<$D$4,YEAR(D17)-1,YEAR(D17)) -> 2010 | G17: Caught Between Moving Objects | H17: GBP | I17: 873.50459 | J17: 0 | K17: 873.50459 | L17: 0 | M17: 0 | N17: 873.50459 | O17: =IF(N17=0,0,1) -> 1 | P17: =N17*$D$8 -> 873.50459 | Q17: =P17*(1+$D$6)^(($D$5-D17)/365.25) -> 1131 | R17: =MIN($D$9,Q17)+MAX(Q17-$D$9-$D$10,0) -> 1131 | S17: =MIN(MAX(Q17-$D$9,0),$D$10) -> 0 | T17: =E17-D17 -> 4 | U17: Closed | V17: =VLOOKUP(F17,'Exposure data (PL)'!$J$3:$L$14,3,FALSE) -> 941.64068
A18: Claim_6 | B18: Name_6 | C18: Public Liability Bodily Injury | D18: 39284 | E18: 39691 | F18: =IF(MONTH(D18)<$D$4,YEAR(D18)-1,YEAR(D18)) -> 2007 | G18: Slip,Trip Or Fall-Same Level | H18: GBP | I18: 866.10894 | J18: 0 | K18: 866.10894 | L18: 0 | M18: 0 | N18: 866.10894 | O18: =IF(N18=0,0,1) -> 1 | P18: =N18*$D$8 -> 866.10894 | Q18: =P18*(1+$D$6)^(($D$5-D18)/365.25) -> 1292.004 | R18: =MIN($D$9,Q18)+MAX(Q18-$D$9-$D$10,0) -> 1292.004 | S18: =MIN(MAX(Q18-$D$9,0),$D$10) -> 0 | T18: =E18-D18 -> 407 | U18: Closed | V18: =VLOOKUP(F18,'Exposure data (PL)'!$J$3:$L$14,3,FALSE) -> 616.17084
A19: Claim_7 | B19: Name_7 | C19: Public Liability Bodily Injury | D19: 40055 | E19: 40111 | F19: =IF(MONTH(D19)<$D$4,YEAR(D19)-1,YEAR(D19)) -> 2009 | G19: Slip,Trip Or Fall-Same Level | H19: GBP | I19: 413.74811 | J19: 0 | K19: 413.74811 | L19: 0 | M19: 0 | N19: 413.74811 | O19: =IF(N19=0,0,1) -> 1 | P19: =N19*$D$8 -> 413.74811 | Q19: =P19*(1+$D$6)^(($D$5-D19)/365.25) -> 556.8 | R19: =MIN($D$9,Q19)+MAX(Q19-$D$9-$D$10,0) -> 556.8 | S19: =MIN(MAX(Q19-$D$9,0),$D$10) -> 0 | T19: =E19-D19 -> 56 | U19: Closed | V19: =VLOOKUP(F19,'Exposure data (PL)'!$J$3:$L$14,3,FALSE) -> 855.15321
A20: Claim_8 | B20: Name_8 | C20: Public Liability Bodily Injury | D20: 39298 | E20: 39487 | F20: =IF(MONTH(D20)<$D$4,YEAR(D20)-1,YEAR(D20)) -> 2007 | G20: Caught Between Moving Objects | H20: GBP | I20: 38016.942 | J20: 0 | K20: 38016.942 | L20: 0 | M20: 0 | N20: 38016.942 | O20: =IF(N20=0,0,1) -> 1 | P20: =N20*$D$8 -> 38016.942 | Q20: =P20*(1+$D$6)^(($D$5-D20)/365.25) -> 56605.2 | R20: =MIN($D$9,Q20)+MAX(Q20-$D$9-$D$10,0) -> 56605.2 | S20: =MIN(MAX(Q20-$D$9,0),$D$10) -> 0 | T20: =E20-D20 -> 189 | U20: Closed | V20: =VLOOKUP(F20,'Exposure data (PL)'!$J$3:$L$14,3,FALSE) -> 616.17084
A21: Claim_9 | B21: Name_9 | C21: Public Liability Bodily Injury | D21: 39937 | E21: 39959 | F21: =IF(MONTH(D21)<$D$4,YEAR(D21)-1,YEAR(D21)) -> 2009 | G21: Slip,Trip Or Fall-Same Level | H21: GBP | I21: 674.55344 | J21: 0 | K21: 674.55344 | L21: 0 | M21: 0 | N21: 674.55344 | O21: =IF(N21=0,0,1) -> 1 | P21: =N21*$D$8 -> 674.55344 | Q21: =P21*(1+$D$6)^(($D$5-D21)/365.25) -> 922.2 | R21: =MIN($D$9,Q21)+MAX(Q21-$D$9-$D$10,0) -> 922.2 | S21: =MIN(MAX(Q21-$D$9,0),$D$10) -> 0 | T21: =E21-D21 -> 22 | U21: Closed | V21: =VLOOKUP(F21,'Exposure data (PL)'!$J$3:$L$14,3,FALSE) -> 855.15321
A22: Claim_10 | B22: Name_10 | C22: Public Liability Bodily Injury | D22: 40489 | E22: 40517 | F22: =IF(MONTH(D22)<$D$4,YEAR(D22)-1,YEAR(D22)) -> 2010 | G22: Slip,Trip Or Fall-Same Level | H22: GBP | I22: 3572.9845 | J22: 0 | K22: 3572.9845 | L22: 0 | M22: 0 | N22: 3572.9845 | O22: =IF(N22=0,0,1) -> 1 | P22: =N22*$D$8 -> 3572.9845 | Q22: =P22*(1+$D$6)^(($D$5-D22)/365.25) -> 4537.5 | R22: =MIN($D$9,Q22)+MAX(Q22-$D$9-$D$10,0) -> 4537.5 | S22: =MIN(MAX(Q22-$D$9,0),$D$10) -> 0 | T22: =E22-D22 -> 28 | U22: Closed | V22: =VLOOKUP(F22,'Exposure data (PL)'!$J$3:$L$14,3,FALSE) -> 941.64068
A23: Claim_11 | B23: Name_11 | C23: Public Liability Bodily Injury | D23: 40421 | E23: 40557 | F23: =IF(MONTH(D23)<$D$4,YEAR(D23)-1,YEAR(D23)) -> 2010 | G23: Slip,Trip Or Fall-Same Level | H23: GBP | I23: 6885.4159 | J23: 0 | K23: 6885.4159 | L23: 0 | M23: 0 | N23: 6885.4159 | O23: =IF(N23=0,0,1) -> 1 | P23: =N23*$D$8 -> 6885.4159 | Q23: =P23*(1+$D$6)^(($D$5-D23)/365.25) -> 8823.9 | R23: =MIN($D$9,Q23)+MAX(Q23-$D$9-$D$10,0) -> 8823.9 | S23: =MIN(MAX(Q23-$D$9,0),$D$10) -> 0 | T23: =E23-D23 -> 136 | U23: Closed | V23: =VLOOKUP(F23,'Exposure data (PL)'!$J$3:$L$14,3,FALSE) -> 941.64068
A24: Claim_12 | B24: Name_12 | C24: Public Liability Property Damage | D24: 39368 | E24: 39451 | F24: =IF(MONTH(D24)<$D$4,YEAR(D24)-1,YEAR(D24)) -> 2007 | G24: Contact With | H24: GBP | I24: 3893.5168 | J24: 0 | K24: 3893.5168 | L24: 0 | M24: 0 | N24: 3893.5168 | O24: =IF(N24=0,0,1) -> 1 | P24: =N24*$D$8 -> 3893.5168 | Q24: =P24*(1+$D$6)^(($D$5-D24)/365.25) -> 5743.284 | R24: =MIN($D$9,Q24)+MAX(Q24-$D$9-$D$10,0) -> 5743.284 | S24: =MIN(MAX(Q24-$D$9,0),$D$10) -> 0 | T24: =E24-D24 -> 83 | U24: Closed | V24: =VLOOKUP(F24,'Exposure data (PL)'!$J$3:$L$14,3,FALSE) -> 616.17084
... A1730: Claim_1718 | B1730: Name_1718 | C1730: Public Liability Property Damage | D1730: 41677 | E1730: 41684 | F1730: =IF(MONTH(D1730)<$D$4,YEAR(D1730)-1,YEAR(D1730)) -> 2013 | G1730: Property Damage | H1730: GBP | I1730: 0 | J1730: 0 | K1730: 0 | L1730: 0 | M1730: 0 | N1730: 0 | O1730: =IF(N1730=0,0,1) -> 0 | P1730: =N1730*$D$8 -> 0 | Q1730: =P1730*(1+$D$6)^(($D$5-D1730)/365.25) -> 0 | R1730: =MIN($D$9,Q1730)+MAX(Q1730-$D$9-$D$10,0) -> 0 | S1730: =MIN(MAX(Q1730-$D$9,0),$D$10) -> 0 | T1730: =E1730-D1730 -> 7 | U1730: Closed | V1730: =VLOOKUP(F1730,'Exposure data (PL)'!$J$3:$L$14,3,FALSE) -> 1226.7615

Sheet Claims data
B3: Claim ID | C3: Loss date | D3: Loss Year | E3: First year reported as non-zero | F3: Type | G3: 2007 | H3: 2008 | I3: 2009 | J3: 2010 | K3: 2011 | L3: 2012 | M3: 2013 | N3: 2014
B4: Claim_1 | C4: 39265 | D4: 2007 | E4: =E6 -> 2007 | F4: Paid | G4: 1303.11 | H4: 1303.11 | I4: 1303.11 | J4: 1303.11 | K4: 1303.11 | L4: 1303.11 | M4: 1303.11 | N4: 1303.11
B5: Claim_1 | C5: 39265 | D5: 2007 | E5: =E6 -> 2007 | F5: O/S | G5: 0 | H5: 0 | I5: 0 | J5: 0 | K5: 0 | L5: 0 | M5: 0 | N5: 0
B6: Claim_1 | C6: 39265 | D6: 2007 | E6: {=MIN(IF(G6:N6>0,($G$3:$N$3)))} -> 2007 | F6: Incurred | G6: 1303.11 | H6: 1303.11 | I6: 1303.11 | J6: 1303.11 | K6: 1303.11 | L6: 1303.11 | M6: 1303.11 | N6: 1303.11
B7: Claim_2 | C7: 39266 | D7: 2007 | E7: =E9 -> 2007 | F7: Paid | G7: 0 | H7: 0 | I7: 180180.25 | J7: 180180.25 | K7: 180180.25 | L7: 432156.76 | M7: 432156.76 | N7: 432156.76
B8: Claim_2 | C8: 39266 | D8: 2007 | E8: =E9 -> 2007 | F8: O/S | G8: 2430000 | H8: 1500000 | I8: 281819.75 | J8: 248146.75 | K8: 251976.5 | L8: 0 | M8: 0 | N8: 0
B9: Claim_2 | C9: 39266 | D9: 2007 | E9: {=MIN(IF(G9:N9>0,($G$3:$N$3)))} -> 2007 | F9: Incurred | G9: 2430000 | H9: 1500000 | I9: 462000 | J9: 428327 | K9: 432156.76 | L9: 432156.76 | M9: 432156.76 | N9: 432156.76
B10: Claim_3 | C10: 39266 | D10: 2007 | E10: =E12 -> 2007 | F10: Paid | G10: 1097.856 | H10: 1097.856 | I10: 1097.856 | J10: 1097.856 | K10: 1097.856 | L10: 1097.856 | M10: 1097.856 | N10: 1097.856
B11: Claim_3 | C11: 39266 | D11: 2007 | E11: =E12 -> 2007 | F11: O/S | G11: 0 | H11: 0 | I11: 0 | J11: 0 | K11: 0 | L11: 0 | M11: 0 | N11: 0
B12: Claim_3 | C12: 39266 | D12: 2007 | E12: {=MIN(IF(G12:N12>0,($G$3:$N$3)))} -> 2007 | F12: Incurred | G12: 1097.856 | H12: 1097.856 | I12: 1097.856 | J12: 1097.856 | K12: 1097.856 | L12: 1097.856 | M12: 1097.856 | N12: 1097.856
B13: Claim_4 | C13: 39267 | D13: 2007 | E13: =E15 -> 2007 | F13: Paid | G13: 0 | H13: 0 | I13: 0 | J13: 0 | K13: 0 | L13: 0 | M13: 0 | N13: 0
B14: Claim_4 | C14: 39267 | D14: 2007 | E14: =E15 -> 2007 | F14: O/S | G14: 114000 | H14: 84000 | I14: 84000 | J14: 0 | K14: 0 | L14: 0 | M14: 0 | N14: 0
B15: Claim_4 | C15: 39267 | D15: 2007 | E15: {=MIN(IF(G15:N15>0,($G$3:$N$3)))} -> 2007 | F15: Incurred | G15: 114000 | H15: 84000 | I15: 84000 | J15: 0 | K15: 0 | L15: 0 | M15: 0 | N15: 0
B16: Claim_5 | C16: 39273 | D16: 2007 | E16: =E18 -> 2008 | F16: Paid | G16: 0 | H16: 0 | I16: 0 | J16: 0 | K16: 0 | L16: 0 | M16: 0 | N16: 0
B17: Claim_5 | C17: 39273 | D17: 2007 | E17: =E18 -> 2008 | F17: O/S | G17: 0 | H17: 30000 | I17: 30000 | J17: 0 | K17: 0 | L17: 0 | M17: 0 | N17: 0
B18: Claim_5 | C18: 39273 | D18: 2007 | E18: {=MIN(IF(G18:N18>0,($G$3:$N$3)))} -> 2008 | F18: Incurred | G18: 0 | H18: 30000 | I18: 30000 | J18: 0 | K18: 0 | L18: 0 | M18: 0 | N18: 0
B19: Claim_6 | C19: 39273 | D19: 2007 | E19: =E21 -> 2007 | F19: Paid | G19: 1551.486 | H19: 1551.486 | I19: 1551.486 | J19: 1551.486 | K19: 1551.486 | L19: 1551.486 | M19: 1551.486 | N19: 1551.486
B20: Claim_6 | C20: 39273 | D20: 2007 | E20: =E21 -> 2007 | F20: O/S | G20: 0 | H20: 0 | I20: 0 | J20: 0 | K20: 0 | L20: 0 | M20: 0 | N20: 0
B21: Claim_6 | C21: 39273 | D21: 2007 | E21: {=MIN(IF(G21:N21>0,($G$3:$N$3)))} -> 2007 | F21: Incurred | G21: 1551.486 | H21: 1551.486 | I21: 1551.486 | J21: 1551.486 | K21: 1551.486 | L21: 1551.486 | M21: 1551.486 | N21: 1551.486
B22: Claim_7 | C22: 39275 | D22: 2007 | E22: =E24 -> 2007 | F22: Paid | G22: 0 | H22: 0 | I22: 0 | J22: 0 | K22: 6687.852 | L22: 6687.852 | M22: 6687.852 | N22: 6687.852
B23: Claim_7 | C23: 39275 | D23: 2007 | E23: =E24 -> 2007 | F23: O/S | G23: 159000 | H23: 180000 | I23: 180000 | J23: 6687.852 | K23: 0 | L23: 0 | M23: 0 | N23: 0
B24: Claim_7 | C24: 39275 | D24: 2007 | E24: {=MIN(IF(G24:N24>0,($G$3:$N$3)))} -> 2007 | F24: Incurred | G24: 159000 | H24: 180000 | I24: 180000 | J24: 6687.852 | K24: 6687.852 | L24: 6687.852 | M24: 6687.852 | N24: 6687.852
B25: Claim_8 | C25: 39278 | D25: 2007 | E25: =E27 -> 2007 | F25: Paid | G25: 0 | H25: 0 | I25: 13063.992 | J25: 30565.2 | K25: 30565.2 | L25: 30565.2 | M25: 30565.2 | N25: 30565.2
B26: Claim_8 | C26: 39278 | D26: 2007 | E26: =E27 -> 2007 | F26: O/S | G26: 30000 | H26: 51000 | I26: 25936.008 | J26: 0 | K26: 0 | L26: 0 | M26: 0 | N26: 0
B27: Claim_8 | C27: 39278 | D27: 2007 | E27: {=MIN(IF(G27:N27>0,($G$3:$N$3)))} -> 2007 | F27: Incurred | G27: 30000 | H27: 51000 | I27: 39000 | J27: 30565.2 | K27: 30565.2 | L27: 30565.2 | M27: 30565.2 | N27: 30565.2
B28: Claim_9 | C28: 39279 | D28: 2007 | E28: =E30 -> 2008 | F28: Paid | G28: 0 | H28: 0 | I28: 0 | J28: 0 | K28: 0 | L28: 0 | M28: 0 | N28: 0
B29: Claim_9 | C29: 39279 | D29: 2007 | E29: =E30 -> 2008 | F29: O/S | G29: 0 | H29: 60000 | I29: 60000 | J29: 60000 | K29: 60000 | L29: 0 | M29: 0 | N29: 0
B30: Claim_9 | C30: 39279 | D30: 2007 | E30: {=MIN(IF(G30:N30>0,($G$3:$N$3)))} -> 2008 | F30: Incurred | G30: 0 | H30: 60000 | I30: 60000 | J30: 60000 | K30: 60000 | L30: 0 | M30: 0 | N30: 0
B31: Claim_10 | C31: 39285 | D31: 2007 | E31: =E33 -> 2007 | F31: Paid | G31: 710.814 | H31: 710.814 | I31: 710.814 | J31: 710.814 | K31: 710.814 | L31: 710.814 | M31: 710.814 | N31: 710.814
B32: Claim_10 | C32: 39285 | D32: 2007 | E32: =E33 -> 2007 | F32: O/S | G32: 0 | H32: 0 | I32: 0 | J32: 0 | K32: 0 | L32: 0 | M32: 0 | N32: 0
B33: Claim_10 | C33: 39285 | D33: 2007 | E33: {=MIN(IF(G33:N33>0,($G$3:$N$3)))} -> 2007 | F33: Incurred | G33: 710.814 | H33: 710.814 | I33: 710.814 | J33: 710.814 | K33: 710.814 | L33: 710.814 | M33: 710.814 | N33: 710.814
B34: Claim_11 | C34: 39286 | D34: 2007 | E34: =E36 -> 2007 | F34: Paid | G34: 0 | H34: 0 | I34: 995895.04 | J34: 995895.04 | K34: 995895.04 | L34: 995895.04 | M34: 995895.04 | N34: 995895.04
B35: Claim_11 | C35: 39286 | D35: 2007 | E35: =E36 -> 2007 | F35: O/S | G35: 900000 | H35: 900000 | I35: 0 | J35: 0 | K35: 0 | L35: 0 | M35: 0 | N35: 0
B36: Claim_11 | C36: 39286 | D36: 2007 | E36: {=MIN(IF(G36:N36>0,($G$3:$N$3)))} -> 2007 | F36: Incurred | G36: 900000 | H36: 900000 | I36: 995895.04 | J36: 995895.04 | K36: 995895.04 | L36: 995895.04 | M36: 995895.04 | N36: 995895.04
B37: Claim_12 | C37: 39287 | D37: 2007 | E37: =E39 -> 2007 | F37: Paid | G37: 0 | H37: 0 | I37: 0 | J37: 0 | K37: 0 | L37: 0 | M37: 0 | N37: 0
B38: Claim_12 | C38: 39287 | D38: 2007 | E38: =E39 -> 2007 | F38: O/S | G38: 39000 | H38: 0 | I38: 0 | J38: 0 | K38: 0 | L38: 0 | M38: 0 | N38: 0
B39: Claim_12 | C39: 39287 | D39: 2007 | E39: {=MIN(IF(G39:N39>0,($G$3:$N$3)))} -> 2007 | F39: Incurred | G39: 39000 | H39: 0 | I39: 0 | J39: 0 | K39: 0 | L39: 0 | M39: 0 | N39: 0
B40: Claim_13 | C40: 39289 | D40: 2007 | E40: =E42 -> 2007 | F40: Paid | G40: 0 | H40: 0 | I40: 113689.43 | J40: 113689.43 | K40: 113689.43 | L40: 113689.43 | M40: 113689.43 | N40: 113689.43
B41: Claim_13 | C41: 39289 | D41: 2007 | E41: =E42 -> 2007 | F41: O/S | G41: 148200 | H41: 165000 | I41: 0 | J41: 0 | K41: 0 | L41: 0 | M41: 0 | N41: 0
B42: Claim_13 | C42: 39289 | D42: 2007 | E42: {=MIN(IF(G42:N42>0,($G$3:$N$3)))} -> 2007 | F42: Incurred | G42: 148200 | H42: 165000 | I42: 113689.43 | J42: 113689.43 | K42: 113689.43 | L42: 113689.43 | M42: 113689.43 | N42: 113689.43
...

Sheet Exposure data (PL)
A1: Historic exposure data | E1: Exposure inflation | F1: 0.04
A3: Fiscal year | B3: Turnover (£m) | D3: Policy year | E3: Turnover (x 1€m) - aligned to policy year | F3: Turnover (x 1€m) - revalued @ 4% p.a. | H3: Employee Numbers | J3: Policy year | K3: Turnover (£m) - aligned to policy year | L3: Turnover (£m) - revalued @ 4% p.a. | N3: Employee Numbers
A4: 2005 | B4: 311.19 | D4: 2002 | E4: =B4 -> 311.19 | F4: =E4*(1+$F$1)^(2012-D4) -> 460.63722 | H4: 12696 | J4: 2005 | K4: =B4 -> 311.19 | L4: =K4*(1+$F$1)^($A$14-J4) -> 460.63722 | N4: 12696
A5: =A4+1 -> 2006 | B5: 381.975 | D5: 2003 | E5: =B5 -> 381.975 | F5: =E5*(1+$F$1)^(2012-D5) -> 543.66953 | H5: 15964 | J5: =J4+1 -> 2006 | K5: =B5 -> 381.975 | L5: =K5*(1+$F$1)^($A$14-J5) -> 543.66953 | N5: 15964
A6: =A5+1 -> 2007 | B6: 450.23 | D6: 2004 | E6: =B6 -> 450.23 | F6: =E6*(1+$F$1)^(2012-D6) -> 616.17084 | H6: 16706 | J6: =J5+1 -> 2007 | K6: =B6 -> 450.23 | L6: =K6*(1+$F$1)^($A$14-J6) -> 616.17084 | N6: 16706
A7: =A6+1 -> 2008 | B7: 514.58 | D7: 2005 | E7: =B7 -> 514.58 | F7: =E7*(1+$F$1)^(2012-D7) -> 677.15217 | H7: 17831 | J7: =J6+1 -> 2008 | K7: =B7 -> 514.58 | L7: =K7*(1+$F$1)^($A$14-J7) -> 677.15217 | N7: 17831
A8: =A7+1 -> 2009 | B8: 675.84 | D8: 2006 | E8: =B8 -> 675.84 | F8: =E8*(1+$F$1)^(2012-D8) -> 855.15321 | H8: 23301 | J8: =J7+1 -> 2009 | K8: =B8 -> 675.84 | L8: =K8*(1+$F$1)^($A$14-J8) -> 855.15321 | N8: 23301
A9: =A8+1 -> 2010 | B9: 773.96 | D9: 2007 | E9: =B9 -> 773.96 | F9: =E9*(1+$F$1)^(2012-D9) -> 941.64068 | H9: 26377 | J9: =J8+1 -> 2010 | K9: =B9 -> 773.96 | L9: =K9*(1+$F$1)^($A$14-J9) -> 941.64068 | N9: 26377
A10: =A9+1 -> 2011 | B10: 837.045 | D10: 2008 | E10: =B10 -> 837.045 | F10: =E10*(1+$F$1)^(2012-D10) -> 979.22426 | H10: 27529 | J10: =J9+1 -> 2011 | K10: =B10 -> 837.045 | L10: =K10*(1+$F$1)^($A$14-J10) -> 979.22426 | N10: 27529
A11: =A10+1 -> 2012 | B11: 1057.54 | D11: 2009 | E11: =B11 -> 1057.54 | F11: =E11*(1+$F$1)^(2012-D11) -> 1189.5887 | H11: 29497 | J11: =J10+1 -> 2012 | K11: =B11 -> 1057.54 | L11: =K11*(1+$F$1)^($A$14-J11) -> 1189.5887 | N11: 29497
A12: =A11+1 -> 2013 | B12: 1134.21 | D12: 2010 | E12: =B12 -> 1134.21 | F12: =E12*(1+$F$1)^(2012-D12) -> 1226.7615 | H12: 32373 | J12: =J11+1 -> 2013 | K12: =B12 -> 1134.21 | L12: =K12*(1+$F$1)^($A$14-J12) -> 1226.7615 | N12: 32373
A13: =A12+1 -> 2014 | B13: 1164.35 | D13: 2011 | E13: =B13 -> 1164.35 | F13: =E13*(1+$F$1)^(2012-D13) -> 1210.924 | H13: 34375 | J13: =J12+1 -> 2014 | K13: =B13 -> 1164.35 | L13: =K13*(1+$F$1)^($A$14-J13) -> 1210.924 | N13: 34375
A14: =A13+1 -> 2015 | B14: 1265 | D14: 2012 | E14: =B14 -> 1265 | F14: =E14*(1+$F$1)^(2012-D14) -> 1265 | H14: 37290 | J14: =J13+1 -> 2015 | K14: =B14 -> 1265 | L14: =K14*(1+$F$1)^($A$14-J14) -> 1265 | N14: 37290
